return { { ["x"] = 0, ["meta"] = { ["fields"] = {  }, ["inventory"] = {  } }, ["param2"] = 0, ["y"] = 0, ["param1"] = 0, ["z"] = 0, ["name"] = "default:wood" }, { ["x"] = 0, ["meta"] = { ["fields"] = {  }, ["inventory"] = {  } }, ["param2"] = 0, ["y"] = 0, ["param1"] = 0, ["z"] = 1, ["name"] = "default:wood" }, { ["x"] = 0, ["meta"] = { ["fields"] = {  }, ["inventory"] = {  } }, ["param2"] = 0, ["y"] = 0, ["param1"] = 0, ["z"] = 2, ["name"] = "default:wood" }, { ["x"] = 0, ["meta"] = { ["fields"] = {  }, ["inventory"] = {  } }, ["param2"] = 0, ["y"] = 0, ["param1"] = 0, ["z"] = 3, ["name"] = "default:wood" }, { ["x"] = 0, ["meta"] = { ["fields"] = {  }, ["inventory"] = {  } }, ["param2"] = 0, ["y"] = 0, ["param1"] = 0, ["z"] = 4, ["name"] = "default:wood" }, { ["x"] = 0, ["meta"] = { ["fields"] = {  }, ["inventory"] = {  } }, ["param2"] = 0, ["y"] = 0, ["param1"] = 15, ["z"] = 5, ["name"] = "default:wood" }, { ["x"] = 0, ["meta"] = { ["fields"] = {  }, ["inventory"] = {  } }, ["param2"] = 0, ["y"] = 0, ["param1"] = 15, ["z"] = 6, ["name"] = "default:wood" }, { ["x"] = 0, ["meta"] = { ["fields"] = {  }, ["inventory"] = {  } }, ["param2"] = 0, ["y"] = 0, ["param1"] = 0, ["z"] = 7, ["name"] = "default:wood" }, { ["x"] = 0, ["meta"] = { ["fields"] = {  }, ["inventory"] = {  } }, ["param2"] = 0, ["y"] = 0, ["param1"] = 0, ["z"] = 8, ["name"] = "default:wood" }, { ["x"] = 0, ["meta"] = { ["fields"] = {  }, ["inventory"] = {  } }, ["param2"] = 0, ["y"] = 0, ["param1"] = 0, ["z"] = 9, ["name"] = "default:wood" }, { ["x"] = 0, ["meta"] = { ["fields"] = {  }, ["inventory"] = {  } }, ["param2"] = 0, ["y"] = 0, ["param1"] = 0, ["z"] = 10, ["name"] = "default:wood" }, { ["x"] = 0, ["meta"] = { ["fields"] = {  }, ["inventory"] = {  } }, ["param2"] = 0, ["y"] = 0, ["param1"] = 0, ["z"] = 11, ["name"] = "default:wood" }, { ["x"] = 0, ["meta"] = { ["fields"] = {  }, ["inventory"] = {  } }, ["param2"] = 0, ["y"] = 1, ["param1"] = 0, ["z"] = 0, ["name"] = "default:wood" }, { ["x"] = 0, ["meta"] = { ["fields"] = {  }, ["inventory"] = {  } }, ["param2"] = 0, ["y"] = 1, ["param1"] = 0, ["z"] = 1, ["name"] = "default:wood" }, { ["x"] = 0, ["meta"] = { ["fields"] = {  }, ["inventory"] = {  } }, ["param2"] = 0, ["y"] = 1, ["param1"] = 0, ["z"] = 2, ["name"] = "default:wood" }, { ["x"] = 0, ["meta"] = { ["fields"] = {  }, ["inventory"] = {  } }, ["param2"] = 0, ["y"] = 1, ["param1"] = 0, ["z"] = 3, ["name"] = "default:wood" }, { ["x"] = 0, ["meta"] = { ["fields"] = {  }, ["inventory"] = {  } }, ["param2"] = 0, ["y"] = 1, ["param1"] = 0, ["z"] = 4, ["name"] = "default:wood" }, { ["x"] = 0, ["meta"] = { ["fields"] = {  }, ["inventory"] = {  } }, ["param2"] = 0, ["y"] = 1, ["param1"] = 0, ["z"] = 5, ["name"] = "default:wood" }, { ["x"] = 0, ["meta"] = { ["fields"] = {  }, ["inventory"] = {  } }, ["param2"] = 0, ["y"] = 1, ["param1"] = 0, ["z"] = 6, ["name"] = "default:wood" }, { ["x"] = 0, ["meta"] = { ["fields"] = {  }, ["inventory"] = {  } }, ["param2"] = 0, ["y"] = 1, ["param1"] = 0, ["z"] = 7, ["name"] = "default:wood" }, { ["x"] = 0, ["meta"] = { ["fields"] = {  }, ["inventory"] = {  } }, ["param2"] = 0, ["y"] = 1, ["param1"] = 0, ["z"] = 8, ["name"] = "default:wood" }, { ["x"] = 0, ["meta"] = { ["fields"] = {  }, ["inventory"] = {  } }, ["param2"] = 0, ["y"] = 1, ["param1"] = 0, ["z"] = 9, ["name"] = "default:wood" }, { ["x"] = 0, ["meta"] = { ["fields"] = {  }, ["inventory"] = {  } }, ["param2"] = 0, ["y"] = 1, ["param1"] = 0, ["z"] = 10, ["name"] = "default:wood" }, { ["x"] = 0, ["meta"] = { ["fields"] = {  }, ["inventory"] = {  } }, ["param2"] = 0, ["y"] = 1, ["param1"] = 0, ["z"] = 11, ["name"] = "default:wood" }, { ["x"] = 0, ["meta"] = { ["fields"] = {  }, ["inventory"] = {  } }, ["param2"] = 0, ["y"] = 2, ["param1"] = 0, ["z"] = 0, ["name"] = "default:wood" }, { ["x"] = 0, ["meta"] = { ["fields"] = {  }, ["inventory"] = {  } }, ["param2"] = 0, ["y"] = 2, ["param1"] = 0, ["z"] = 1, ["name"] = "default:wood" }, { ["x"] = 0, ["meta"] = { ["fields"] = {  }, ["inventory"] = {  } }, ["param2"] = 0, ["y"] = 2, ["param1"] = 0, ["z"] = 2, ["name"] = "default:wood" }, { ["x"] = 0, ["meta"] = { ["fields"] = {  }, ["inventory"] = {  } }, ["param2"] = 0, ["y"] = 2, ["param1"] = 0, ["z"] = 3, ["name"] = "default:wood" }, { ["x"] = 0, ["meta"] = { ["fields"] = {  }, ["inventory"] = {  } }, ["param2"] = 0, ["y"] = 2, ["param1"] = 0, ["z"] = 4, ["name"] = "default:wood" }, { ["x"] = 0, ["meta"] = { ["fields"] = {  }, ["inventory"] = {  } }, ["param2"] = 0, ["y"] = 2, ["param1"] = 0, ["z"] = 5, ["name"] = "default:wood" }, { ["x"] = 0, ["meta"] = { ["fields"] = {  }, ["inventory"] = {  } }, ["param2"] = 0, ["y"] = 2, ["param1"] = 0, ["z"] = 6, ["name"] = "default:wood" }, { ["x"] = 0, ["meta"] = { ["fields"] = {  }, ["inventory"] = {  } }, ["param2"] = 0, ["y"] = 2, ["param1"] = 0, ["z"] = 7, ["name"] = "default:wood" }, { ["x"] = 0, ["meta"] = { ["fields"] = {  }, ["inventory"] = {  } }, ["param2"] = 0, ["y"] = 2, ["param1"] = 0, ["z"] = 8, ["name"] = "default:wood" }, { ["x"] = 0, ["meta"] = { ["fields"] = {  }, ["inventory"] = {  } }, ["param2"] = 0, ["y"] = 2, ["param1"] = 0, ["z"] = 9, ["name"] = "default:wood" }, { ["x"] = 0, ["meta"] = { ["fields"] = {  }, ["inventory"] = {  } }, ["param2"] = 0, ["y"] = 2, ["param1"] = 0, ["z"] = 10, ["name"] = "default:wood" }, { ["x"] = 0, ["meta"] = { ["fields"] = {  }, ["inventory"] = {  } }, ["param2"] = 0, ["y"] = 2, ["param1"] = 0, ["z"] = 11, ["name"] = "default:wood" }, { ["x"] = 0, ["meta"] = { ["fields"] = {  }, ["inventory"] = {  } }, ["param2"] = 0, ["y"] = 3, ["param1"] = 77, ["z"] = 0, ["name"] = "stairs:slab_wood" }, { ["x"] = 0, ["meta"] = { ["fields"] = {  }, ["inventory"] = {  } }, ["param2"] = 1, ["y"] = 3, ["param1"] = 61, ["z"] = 1, ["name"] = "stairs:stair_wood" }, { ["x"] = 0, ["meta"] = { ["fields"] = {  }, ["inventory"] = {  } }, ["param2"] = 1, ["y"] = 3, ["param1"] = 77, ["z"] = 2, ["name"] = "stairs:stair_wood" }, { ["x"] = 0, ["meta"] = { ["fields"] = {  }, ["inventory"] = {  } }, ["param2"] = 1, ["y"] = 3, ["param1"] = 61, ["z"] = 3, ["name"] = "stairs:stair_wood" }, { ["x"] = 0, ["meta"] = { ["fields"] = {  }, ["inventory"] = {  } }, ["param2"] = 1, ["y"] = 3, ["param1"] = 45, ["z"] = 4, ["name"] = "stairs:stair_wood" }, { ["x"] = 0, ["meta"] = { ["fields"] = {  }, ["inventory"] = {  } }, ["param2"] = 1, ["y"] = 3, ["param1"] = 29, ["z"] = 5, ["name"] = "stairs:stair_wood" }, { ["x"] = 0, ["meta"] = { ["fields"] = {  }, ["inventory"] = {  } }, ["param2"] = 1, ["y"] = 3, ["param1"] = 29, ["z"] = 6, ["name"] = "stairs:stair_wood" }, { ["x"] = 0, ["meta"] = { ["fields"] = {  }, ["inventory"] = {  } }, ["param2"] = 1, ["y"] = 3, ["param1"] = 45, ["z"] = 7, ["name"] = "stairs:stair_wood" }, { ["x"] = 0, ["meta"] = { ["fields"] = {  }, ["inventory"] = {  } }, ["param2"] = 1, ["y"] = 3, ["param1"] = 61, ["z"] = 8, ["name"] = "stairs:stair_wood" }, { ["x"] = 0, ["meta"] = { ["fields"] = {  }, ["inventory"] = {  } }, ["param2"] = 1, ["y"] = 3, ["param1"] = 77, ["z"] = 9, ["name"] = "stairs:stair_wood" }, { ["x"] = 0, ["meta"] = { ["fields"] = {  }, ["inventory"] = {  } }, ["param2"] = 1, ["y"] = 3, ["param1"] = 61, ["z"] = 10, ["name"] = "stairs:stair_wood" }, { ["x"] = 0, ["meta"] = { ["fields"] = {  }, ["inventory"] = {  } }, ["param2"] = 0, ["y"] = 3, ["param1"] = 45, ["z"] = 11, ["name"] = "stairs:slab_wood" }, { ["x"] = 0, ["meta"] = { ["fields"] = {  }, ["inventory"] = {  } }, ["param2"] = 0, ["y"] = 4, ["param1"] = 79, ["z"] = 0, ["name"] = "mg:ignore" }, { ["x"] = 0, ["meta"] = { ["fields"] = {  }, ["inventory"] = {  } }, ["param2"] = 0, ["y"] = 4, ["param1"] = 95, ["z"] = 1, ["name"] = "mg:ignore" }, { ["x"] = 0, ["meta"] = { ["fields"] = {  }, ["inventory"] = {  } }, ["param2"] = 0, ["y"] = 4, ["param1"] = 79, ["z"] = 2, ["name"] = "mg:ignore" }, { ["x"] = 0, ["meta"] = { ["fields"] = {  }, ["inventory"] = {  } }, ["param2"] = 0, ["y"] = 4, ["param1"] = 63, ["z"] = 3, ["name"] = "mg:ignore" }, { ["x"] = 0, ["meta"] = { ["fields"] = {  }, ["inventory"] = {  } }, ["param2"] = 0, ["y"] = 4, ["param1"] = 47, ["z"] = 4, ["name"] = "mg:ignore" }, { ["x"] = 0, ["meta"] = { ["fields"] = {  }, ["inventory"] = {  } }, ["param2"] = 0, ["y"] = 4, ["param1"] = 31, ["z"] = 5, ["name"] = "mg:ignore" }, { ["x"] = 0, ["meta"] = { ["fields"] = {  }, ["inventory"] = {  } }, ["param2"] = 0, ["y"] = 4, ["param1"] = 15, ["z"] = 6, ["name"] = "mg:ignore" }, { ["x"] = 0, ["meta"] = { ["fields"] = {  }, ["inventory"] = {  } }, ["param2"] = 0, ["y"] = 4, ["param1"] = 15, ["z"] = 7, ["name"] = "mg:ignore" }, { ["x"] = 0, ["meta"] = { ["fields"] = {  }, ["inventory"] = {  } }, ["param2"] = 0, ["y"] = 4, ["param1"] = 15, ["z"] = 8, ["name"] = "mg:ignore" }, { ["x"] = 0, ["meta"] = { ["fields"] = {  }, ["inventory"] = {  } }, ["param2"] = 0, ["y"] = 4, ["param1"] = 15, ["z"] = 9, ["name"] = "mg:ignore" }, { ["x"] = 0, ["meta"] = { ["fields"] = {  }, ["inventory"] = {  } }, ["param2"] = 0, ["y"] = 4, ["param1"] = 15, ["z"] = 10, ["name"] = "mg:ignore" }, { ["x"] = 0, ["meta"] = { ["fields"] = {  }, ["inventory"] = {  } }, ["param2"] = 0, ["y"] = 4, ["param1"] = 0, ["z"] = 11, ["name"] = "mg:ignore" }, { ["x"] = 0, ["meta"] = { ["fields"] = {  }, ["inventory"] = {  } }, ["param2"] = 0, ["y"] = 5, ["param1"] = 63, ["z"] = 0, ["name"] = "mg:ignore" }, { ["x"] = 0, ["meta"] = { ["fields"] = {  }, ["inventory"] = {  } }, ["param2"] = 0, ["y"] = 5, ["param1"] = 79, ["z"] = 1, ["name"] = "mg:ignore" }, { ["x"] = 0, ["meta"] = { ["fields"] = {  }, ["inventory"] = {  } }, ["param2"] = 0, ["y"] = 5, ["param1"] = 63, ["z"] = 2, ["name"] = "mg:ignore" }, { ["x"] = 0, ["meta"] = { ["fields"] = {  }, ["inventory"] = {  } }, ["param2"] = 0, ["y"] = 5, ["param1"] = 47, ["z"] = 3, ["name"] = "mg:ignore" }, { ["x"] = 0, ["meta"] = { ["fields"] = {  }, ["inventory"] = {  } }, ["param2"] = 0, ["y"] = 5, ["param1"] = 31, ["z"] = 4, ["name"] = "mg:ignore" }, { ["x"] = 0, ["meta"] = { ["fields"] = {  }, ["inventory"] = {  } }, ["param2"] = 0, ["y"] = 5, ["param1"] = 15, ["z"] = 5, ["name"] = "mg:ignore" }, { ["x"] = 0, ["meta"] = { ["fields"] = {  }, ["inventory"] = {  } }, ["param2"] = 0, ["y"] = 5, ["param1"] = 15, ["z"] = 6, ["name"] = "mg:ignore" }, { ["x"] = 0, ["meta"] = { ["fields"] = {  }, ["inventory"] = {  } }, ["param2"] = 0, ["y"] = 5, ["param1"] = 15, ["z"] = 7, ["name"] = "mg:ignore" }, { ["x"] = 0, ["meta"] = { ["fields"] = {  }, ["inventory"] = {  } }, ["param2"] = 0, ["y"] = 5, ["param1"] = 15, ["z"] = 8, ["name"] = "mg:ignore" }, { ["x"] = 0, ["meta"] = { ["fields"] = {  }, ["inventory"] = {  } }, ["param2"] = 0, ["y"] = 5, ["param1"] = 15, ["z"] = 9, ["name"] = "mg:ignore" }, { ["x"] = 0, ["meta"] = { ["fields"] = {  }, ["inventory"] = {  } }, ["param2"] = 0, ["y"] = 5, ["param1"] = 15, ["z"] = 10, ["name"] = "mg:ignore" }, { ["x"] = 0, ["meta"] = { ["fields"] = {  }, ["inventory"] = {  } }, ["param2"] = 0, ["y"] = 5, ["param1"] = 0, ["z"] = 11, ["name"] = "mg:ignore" }, { ["x"] = 1, ["meta"] = { ["fields"] = {  }, ["inventory"] = {  } }, ["param2"] = 0, ["y"] = 0, ["param1"] = 0, ["z"] = 0, ["name"] = "default:wood" }, { ["x"] = 1, ["meta"] = { ["fields"] = {  }, ["inventory"] = {  } }, ["param2"] = 0, ["y"] = 0, ["param1"] = 0, ["z"] = 1, ["name"] = "default:wood" }, { ["x"] = 1, ["meta"] = { ["fields"] = {  }, ["inventory"] = {  } }, ["param2"] = 0, ["y"] = 0, ["param1"] = 0, ["z"] = 2, ["name"] = "default:wood" }, { ["x"] = 1, ["meta"] = { ["fields"] = {  }, ["inventory"] = {  } }, ["param2"] = 0, ["y"] = 0, ["param1"] = 0, ["z"] = 3, ["name"] = "default:wood" }, { ["x"] = 1, ["meta"] = { ["fields"] = {  }, ["inventory"] = {  } }, ["param2"] = 0, ["y"] = 0, ["param1"] = 0, ["z"] = 4, ["name"] = "default:wood" }, { ["x"] = 1, ["meta"] = { ["fields"] = {  }, ["inventory"] = {  } }, ["param2"] = 0, ["y"] = 0, ["param1"] = 15, ["z"] = 5, ["name"] = "default:wood" }, { ["x"] = 1, ["meta"] = { ["fields"] = {  }, ["inventory"] = {  } }, ["param2"] = 0, ["y"] = 0, ["param1"] = 15, ["z"] = 6, ["name"] = "default:wood" }, { ["x"] = 1, ["meta"] = { ["fields"] = {  }, ["inventory"] = {  } }, ["param2"] = 0, ["y"] = 0, ["param1"] = 15, ["z"] = 7, ["name"] = "default:wood" }, { ["x"] = 1, ["meta"] = { ["fields"] = {  }, ["inventory"] = {  } }, ["param2"] = 0, ["y"] = 0, ["param1"] = 15, ["z"] = 8, ["name"] = "default:wood" }, { ["x"] = 1, ["meta"] = { ["fields"] = {  }, ["inventory"] = {  } }, ["param2"] = 0, ["y"] = 0, ["param1"] = 15, ["z"] = 9, ["name"] = "default:wood" }, { ["x"] = 1, ["meta"] = { ["fields"] = {  }, ["inventory"] = {  } }, ["param2"] = 0, ["y"] = 0, ["param1"] = 15, ["z"] = 10, ["name"] = "default:wood" }, { ["x"] = 1, ["meta"] = { ["fields"] = {  }, ["inventory"] = {  } }, ["param2"] = 0, ["y"] = 0, ["param1"] = 15, ["z"] = 11, ["name"] = "default:wood" }, { ["x"] = 1, ["meta"] = { ["fields"] = {  }, ["inventory"] = {  } }, ["param2"] = 0, ["y"] = 1, ["param1"] = 0, ["z"] = 0, ["name"] = "default:wood" }, { ["x"] = 1, ["meta"] = { ["fields"] = {  }, ["inventory"] = {  } }, ["param2"] = 0, ["y"] = 1, ["param1"] = 0, ["z"] = 1, ["name"] = "default:wood" }, { ["x"] = 1, ["meta"] = { ["fields"] = { ["formspec"] = "size[8,7;]bgcolor[#080808BB;true]background[5,5;1,1;gui_formbg.png;true]listcolors[#00000069;#5A5A5A;#141318;#30434C;#FFF]list[context;books;0,0.3;8,2;]list[current_player;main;0,2.85;8,1;]list[current_player;main;0,4.08;8,3;8]image[0,2.85;1,1;gui_hb_bg.png]image[1,2.85;1,1;gui_hb_bg.png]image[2,2.85;1,1;gui_hb_bg.png]image[3,2.85;1,1;gui_hb_bg.png]image[4,2.85;1,1;gui_hb_bg.png]image[5,2.85;1,1;gui_hb_bg.png]image[6,2.85;1,1;gui_hb_bg.png]image[7,2.85;1,1;gui_hb_bg.png]" }, ["inventory"] = { ["books"] = { "", "", "", "", "", "", "", "", "", "", "", "", "", "", "", "" } } }, ["param2"] = 0, ["y"] = 1, ["param1"] = 0, ["z"] = 2, ["name"] = "default:bookshelf" }, { ["x"] = 1, ["meta"] = { ["fields"] = { ["formspec"] = "size[8,7;]bgcolor[#080808BB;true]background[5,5;1,1;gui_formbg.png;true]listcolors[#00000069;#5A5A5A;#141318;#30434C;#FFF]list[context;books;0,0.3;8,2;]list[current_player;main;0,2.85;8,1;]list[current_player;main;0,4.08;8,3;8]image[0,2.85;1,1;gui_hb_bg.png]image[1,2.85;1,1;gui_hb_bg.png]image[2,2.85;1,1;gui_hb_bg.png]image[3,2.85;1,1;gui_hb_bg.png]image[4,2.85;1,1;gui_hb_bg.png]image[5,2.85;1,1;gui_hb_bg.png]image[6,2.85;1,1;gui_hb_bg.png]image[7,2.85;1,1;gui_hb_bg.png]" }, ["inventory"] = { ["books"] = { "", "", "", "", "", "", "", "", "", "", "", "", "", "", "", "" } } }, ["param2"] = 0, ["y"] = 1, ["param1"] = 0, ["z"] = 3, ["name"] = "default:bookshelf" }, { ["x"] = 1, ["meta"] = { ["fields"] = { ["formspec"] = "size[8,7;]bgcolor[#080808BB;true]background[5,5;1,1;gui_formbg.png;true]listcolors[#00000069;#5A5A5A;#141318;#30434C;#FFF]list[context;books;0,0.3;8,2;]list[current_player;main;0,2.85;8,1;]list[current_player;main;0,4.08;8,3;8]image[0,2.85;1,1;gui_hb_bg.png]image[1,2.85;1,1;gui_hb_bg.png]image[2,2.85;1,1;gui_hb_bg.png]image[3,2.85;1,1;gui_hb_bg.png]image[4,2.85;1,1;gui_hb_bg.png]image[5,2.85;1,1;gui_hb_bg.png]image[6,2.85;1,1;gui_hb_bg.png]image[7,2.85;1,1;gui_hb_bg.png]" }, ["inventory"] = { ["books"] = { "", "", "", "", "", "", "", "", "", "", "", "", "", "", "", "" } } }, ["param2"] = 0, ["y"] = 1, ["param1"] = 0, ["z"] = 4, ["name"] = "default:bookshelf" }, { ["x"] = 1, ["meta"] = { ["fields"] = { ["formspec"] = "size[8,7;]bgcolor[#080808BB;true]background[5,5;1,1;gui_formbg.png;true]listcolors[#00000069;#5A5A5A;#141318;#30434C;#FFF]list[context;books;0,0.3;8,2;]list[current_player;main;0,2.85;8,1;]list[current_player;main;0,4.08;8,3;8]image[0,2.85;1,1;gui_hb_bg.png]image[1,2.85;1,1;gui_hb_bg.png]image[2,2.85;1,1;gui_hb_bg.png]image[3,2.85;1,1;gui_hb_bg.png]image[4,2.85;1,1;gui_hb_bg.png]image[5,2.85;1,1;gui_hb_bg.png]image[6,2.85;1,1;gui_hb_bg.png]image[7,2.85;1,1;gui_hb_bg.png]" }, ["inventory"] = { ["books"] = { "", "", "", "", "", "", "", "", "", "", "", "", "", "", "", "" } } }, ["param2"] = 0, ["y"] = 1, ["param1"] = 0, ["z"] = 5, ["name"] = "default:bookshelf" }, { ["x"] = 1, ["meta"] = { ["fields"] = { ["formspec"] = "size[8,7;]bgcolor[#080808BB;true]background[5,5;1,1;gui_formbg.png;true]listcolors[#00000069;#5A5A5A;#141318;#30434C;#FFF]list[context;books;0,0.3;8,2;]list[current_player;main;0,2.85;8,1;]list[current_player;main;0,4.08;8,3;8]image[0,2.85;1,1;gui_hb_bg.png]image[1,2.85;1,1;gui_hb_bg.png]image[2,2.85;1,1;gui_hb_bg.png]image[3,2.85;1,1;gui_hb_bg.png]image[4,2.85;1,1;gui_hb_bg.png]image[5,2.85;1,1;gui_hb_bg.png]image[6,2.85;1,1;gui_hb_bg.png]image[7,2.85;1,1;gui_hb_bg.png]" }, ["inventory"] = { ["books"] = { "", "", "", "", "", "", "default:book", "", "", "", "default:book", "", "", "", "default:book", "" } } }, ["param2"] = 0, ["y"] = 1, ["param1"] = 0, ["z"] = 6, ["name"] = "default:bookshelf" }, { ["x"] = 1, ["meta"] = { ["fields"] = { ["formspec"] = "size[8,7;]bgcolor[#080808BB;true]background[5,5;1,1;gui_formbg.png;true]listcolors[#00000069;#5A5A5A;#141318;#30434C;#FFF]list[context;books;0,0.3;8,2;]list[current_player;main;0,2.85;8,1;]list[current_player;main;0,4.08;8,3;8]image[0,2.85;1,1;gui_hb_bg.png]image[1,2.85;1,1;gui_hb_bg.png]image[2,2.85;1,1;gui_hb_bg.png]image[3,2.85;1,1;gui_hb_bg.png]image[4,2.85;1,1;gui_hb_bg.png]image[5,2.85;1,1;gui_hb_bg.png]image[6,2.85;1,1;gui_hb_bg.png]image[7,2.85;1,1;gui_hb_bg.png]" }, ["inventory"] = { ["books"] = { "", "", "", "", "", "", "", "", "", "", "", "", "", "", "", "" } } }, ["param2"] = 0, ["y"] = 1, ["param1"] = 0, ["z"] = 7, ["name"] = "default:bookshelf" }, { ["x"] = 1, ["meta"] = { ["fields"] = { ["formspec"] = "size[8,7;]bgcolor[#080808BB;true]background[5,5;1,1;gui_formbg.png;true]listcolors[#00000069;#5A5A5A;#141318;#30434C;#FFF]list[context;books;0,0.3;8,2;]list[current_player;main;0,2.85;8,1;]list[current_player;main;0,4.08;8,3;8]image[0,2.85;1,1;gui_hb_bg.png]image[1,2.85;1,1;gui_hb_bg.png]image[2,2.85;1,1;gui_hb_bg.png]image[3,2.85;1,1;gui_hb_bg.png]image[4,2.85;1,1;gui_hb_bg.png]image[5,2.85;1,1;gui_hb_bg.png]image[6,2.85;1,1;gui_hb_bg.png]image[7,2.85;1,1;gui_hb_bg.png]" }, ["inventory"] = { ["books"] = { "", "", "", "", "", "", "", "", "", "", "", "", "", "", "", "" } } }, ["param2"] = 0, ["y"] = 1, ["param1"] = 0, ["z"] = 8, ["name"] = "default:bookshelf" }, { ["x"] = 1, ["meta"] = { ["fields"] = { ["formspec"] = "size[8,7;]bgcolor[#080808BB;true]background[5,5;1,1;gui_formbg.png;true]listcolors[#00000069;#5A5A5A;#141318;#30434C;#FFF]list[context;books;0,0.3;8,2;]list[current_player;main;0,2.85;8,1;]list[current_player;main;0,4.08;8,3;8]image[0,2.85;1,1;gui_hb_bg.png]image[1,2.85;1,1;gui_hb_bg.png]image[2,2.85;1,1;gui_hb_bg.png]image[3,2.85;1,1;gui_hb_bg.png]image[4,2.85;1,1;gui_hb_bg.png]image[5,2.85;1,1;gui_hb_bg.png]image[6,2.85;1,1;gui_hb_bg.png]image[7,2.85;1,1;gui_hb_bg.png]" }, ["inventory"] = { ["books"] = { "", "", "", "", "", "", "", "", "", "", "", "", "", "", "", "" } } }, ["param2"] = 0, ["y"] = 1, ["param1"] = 0, ["z"] = 9, ["name"] = "default:bookshelf" }, { ["x"] = 1, ["meta"] = { ["fields"] = {  }, ["inventory"] = {  } }, ["param2"] = 0, ["y"] = 1, ["param1"] = 0, ["z"] = 10, ["name"] = "default:wood" }, { ["x"] = 1, ["meta"] = { ["fields"] = {  }, ["inventory"] = {  } }, ["param2"] = 0, ["y"] = 1, ["param1"] = 0, ["z"] = 11, ["name"] = "default:wood" }, { ["x"] = 1, ["meta"] = { ["fields"] = {  }, ["inventory"] = {  } }, ["param2"] = 0, ["y"] = 2, ["param1"] = 0, ["z"] = 0, ["name"] = "default:wood" }, { ["x"] = 1, ["meta"] = { ["fields"] = {  }, ["inventory"] = {  } }, ["param2"] = 0, ["y"] = 2, ["param1"] = 0, ["z"] = 1, ["name"] = "default:wood" }, { ["x"] = 1, ["meta"] = { ["fields"] = { ["formspec"] = "size[8,7;]bgcolor[#080808BB;true]background[5,5;1,1;gui_formbg.png;true]listcolors[#00000069;#5A5A5A;#141318;#30434C;#FFF]list[context;books;0,0.3;8,2;]list[current_player;main;0,2.85;8,1;]list[current_player;main;0,4.08;8,3;8]image[0,2.85;1,1;gui_hb_bg.png]image[1,2.85;1,1;gui_hb_bg.png]image[2,2.85;1,1;gui_hb_bg.png]image[3,2.85;1,1;gui_hb_bg.png]image[4,2.85;1,1;gui_hb_bg.png]image[5,2.85;1,1;gui_hb_bg.png]image[6,2.85;1,1;gui_hb_bg.png]image[7,2.85;1,1;gui_hb_bg.png]" }, ["inventory"] = { ["books"] = { "", "", "", "", "", "", "", "", "", "", "", "", "", "", "", "" } } }, ["param2"] = 0, ["y"] = 2, ["param1"] = 0, ["z"] = 2, ["name"] = "default:bookshelf" }, { ["x"] = 1, ["meta"] = { ["fields"] = { ["formspec"] = "size[8,7;]bgcolor[#080808BB;true]background[5,5;1,1;gui_formbg.png;true]listcolors[#00000069;#5A5A5A;#141318;#30434C;#FFF]list[context;books;0,0.3;8,2;]list[current_player;main;0,2.85;8,1;]list[current_player;main;0,4.08;8,3;8]image[0,2.85;1,1;gui_hb_bg.png]image[1,2.85;1,1;gui_hb_bg.png]image[2,2.85;1,1;gui_hb_bg.png]image[3,2.85;1,1;gui_hb_bg.png]image[4,2.85;1,1;gui_hb_bg.png]image[5,2.85;1,1;gui_hb_bg.png]image[6,2.85;1,1;gui_hb_bg.png]image[7,2.85;1,1;gui_hb_bg.png]" }, ["inventory"] = { ["books"] = { "", "", "", "", "", "", "", "", "", "", "", "", "", "", "", "" } } }, ["param2"] = 0, ["y"] = 2, ["param1"] = 0, ["z"] = 3, ["name"] = "default:bookshelf" }, { ["x"] = 1, ["meta"] = { ["fields"] = { ["formspec"] = "size[8,7;]bgcolor[#080808BB;true]background[5,5;1,1;gui_formbg.png;true]listcolors[#00000069;#5A5A5A;#141318;#30434C;#FFF]list[context;books;0,0.3;8,2;]list[current_player;main;0,2.85;8,1;]list[current_player;main;0,4.08;8,3;8]image[0,2.85;1,1;gui_hb_bg.png]image[1,2.85;1,1;gui_hb_bg.png]image[2,2.85;1,1;gui_hb_bg.png]image[3,2.85;1,1;gui_hb_bg.png]image[4,2.85;1,1;gui_hb_bg.png]image[5,2.85;1,1;gui_hb_bg.png]image[6,2.85;1,1;gui_hb_bg.png]image[7,2.85;1,1;gui_hb_bg.png]" }, ["inventory"] = { ["books"] = { "", "", "", "", "", "default:book", "", "", "", "", "", "", "", "", "", "" } } }, ["param2"] = 0, ["y"] = 2, ["param1"] = 0, ["z"] = 4, ["name"] = "default:bookshelf" }, { ["x"] = 1, ["meta"] = { ["fields"] = { ["formspec"] = "size[8,7;]bgcolor[#080808BB;true]background[5,5;1,1;gui_formbg.png;true]listcolors[#00000069;#5A5A5A;#141318;#30434C;#FFF]list[context;books;0,0.3;8,2;]list[current_player;main;0,2.85;8,1;]list[current_player;main;0,4.08;8,3;8]image[0,2.85;1,1;gui_hb_bg.png]image[1,2.85;1,1;gui_hb_bg.png]image[2,2.85;1,1;gui_hb_bg.png]image[3,2.85;1,1;gui_hb_bg.png]image[4,2.85;1,1;gui_hb_bg.png]image[5,2.85;1,1;gui_hb_bg.png]image[6,2.85;1,1;gui_hb_bg.png]image[7,2.85;1,1;gui_hb_bg.png]" }, ["inventory"] = { ["books"] = { "", "", "", "", "", "", "", "", "", "", "", "", "", "", "", "" } } }, ["param2"] = 0, ["y"] = 2, ["param1"] = 0, ["z"] = 5, ["name"] = "default:bookshelf" }, { ["x"] = 1, ["meta"] = { ["fields"] = { ["formspec"] = "size[8,7;]bgcolor[#080808BB;true]background[5,5;1,1;gui_formbg.png;true]listcolors[#00000069;#5A5A5A;#141318;#30434C;#FFF]list[context;books;0,0.3;8,2;]list[current_player;main;0,2.85;8,1;]list[current_player;main;0,4.08;8,3;8]image[0,2.85;1,1;gui_hb_bg.png]image[1,2.85;1,1;gui_hb_bg.png]image[2,2.85;1,1;gui_hb_bg.png]image[3,2.85;1,1;gui_hb_bg.png]image[4,2.85;1,1;gui_hb_bg.png]image[5,2.85;1,1;gui_hb_bg.png]image[6,2.85;1,1;gui_hb_bg.png]image[7,2.85;1,1;gui_hb_bg.png]" }, ["inventory"] = { ["books"] = { "", "", "", "", "", "", "", "", "", "", "", "", "", "", "", "" } } }, ["param2"] = 0, ["y"] = 2, ["param1"] = 0, ["z"] = 6, ["name"] = "default:bookshelf" }, { ["x"] = 1, ["meta"] = { ["fields"] = { ["formspec"] = "size[8,7;]bgcolor[#080808BB;true]background[5,5;1,1;gui_formbg.png;true]listcolors[#00000069;#5A5A5A;#141318;#30434C;#FFF]list[context;books;0,0.3;8,2;]list[current_player;main;0,2.85;8,1;]list[current_player;main;0,4.08;8,3;8]image[0,2.85;1,1;gui_hb_bg.png]image[1,2.85;1,1;gui_hb_bg.png]image[2,2.85;1,1;gui_hb_bg.png]image[3,2.85;1,1;gui_hb_bg.png]image[4,2.85;1,1;gui_hb_bg.png]image[5,2.85;1,1;gui_hb_bg.png]image[6,2.85;1,1;gui_hb_bg.png]image[7,2.85;1,1;gui_hb_bg.png]" }, ["inventory"] = { ["books"] = { "", "", "", "", "", "", "", "", "", "", "", "", "", "", "", "" } } }, ["param2"] = 0, ["y"] = 2, ["param1"] = 0, ["z"] = 7, ["name"] = "default:bookshelf" }, { ["x"] = 1, ["meta"] = { ["fields"] = { ["formspec"] = "size[8,7;]bgcolor[#080808BB;true]background[5,5;1,1;gui_formbg.png;true]listcolors[#00000069;#5A5A5A;#141318;#30434C;#FFF]list[context;books;0,0.3;8,2;]list[current_player;main;0,2.85;8,1;]list[current_player;main;0,4.08;8,3;8]image[0,2.85;1,1;gui_hb_bg.png]image[1,2.85;1,1;gui_hb_bg.png]image[2,2.85;1,1;gui_hb_bg.png]image[3,2.85;1,1;gui_hb_bg.png]image[4,2.85;1,1;gui_hb_bg.png]image[5,2.85;1,1;gui_hb_bg.png]image[6,2.85;1,1;gui_hb_bg.png]image[7,2.85;1,1;gui_hb_bg.png]" }, ["inventory"] = { ["books"] = { "", "", "", "", "", "", "", "", "", "", "", "", "", "", "", "" } } }, ["param2"] = 0, ["y"] = 2, ["param1"] = 0, ["z"] = 8, ["name"] = "default:bookshelf" }, { ["x"] = 1, ["meta"] = { ["fields"] = { ["formspec"] = "size[8,7;]bgcolor[#080808BB;true]background[5,5;1,1;gui_formbg.png;true]listcolors[#00000069;#5A5A5A;#141318;#30434C;#FFF]list[context;books;0,0.3;8,2;]list[current_player;main;0,2.85;8,1;]list[current_player;main;0,4.08;8,3;8]image[0,2.85;1,1;gui_hb_bg.png]image[1,2.85;1,1;gui_hb_bg.png]image[2,2.85;1,1;gui_hb_bg.png]image[3,2.85;1,1;gui_hb_bg.png]image[4,2.85;1,1;gui_hb_bg.png]image[5,2.85;1,1;gui_hb_bg.png]image[6,2.85;1,1;gui_hb_bg.png]image[7,2.85;1,1;gui_hb_bg.png]" }, ["inventory"] = { ["books"] = { "", "", "", "", "", "", "", "", "", "", "", "", "", "", "", "" } } }, ["param2"] = 0, ["y"] = 2, ["param1"] = 0, ["z"] = 9, ["name"] = "default:bookshelf" }, { ["x"] = 1, ["meta"] = { ["fields"] = {  }, ["inventory"] = {  } }, ["param2"] = 0, ["y"] = 2, ["param1"] = 0, ["z"] = 10, ["name"] = "default:wood" }, { ["x"] = 1, ["meta"] = { ["fields"] = {  }, ["inventory"] = {  } }, ["param2"] = 0, ["y"] = 2, ["param1"] = 0, ["z"] = 11, ["name"] = "default:wood" }, { ["x"] = 1, ["meta"] = { ["fields"] = {  }, ["inventory"] = {  } }, ["param2"] = 0, ["y"] = 3, ["param1"] = 93, ["z"] = 0, ["name"] = "stairs:stair_wood" }, { ["x"] = 1, ["meta"] = { ["fields"] = {  }, ["inventory"] = {  } }, ["param2"] = 0, ["y"] = 3, ["param1"] = 0, ["z"] = 1, ["name"] = "default:wood" }, { ["x"] = 1, ["meta"] = { ["fields"] = { ["formspec"] = "size[8,7;]bgcolor[#080808BB;true]background[5,5;1,1;gui_formbg.png;true]listcolors[#00000069;#5A5A5A;#141318;#30434C;#FFF]list[context;books;0,0.3;8,2;]list[current_player;main;0,2.85;8,1;]list[current_player;main;0,4.08;8,3;8]image[0,2.85;1,1;gui_hb_bg.png]image[1,2.85;1,1;gui_hb_bg.png]image[2,2.85;1,1;gui_hb_bg.png]image[3,2.85;1,1;gui_hb_bg.png]image[4,2.85;1,1;gui_hb_bg.png]image[5,2.85;1,1;gui_hb_bg.png]image[6,2.85;1,1;gui_hb_bg.png]image[7,2.85;1,1;gui_hb_bg.png]" }, ["inventory"] = { ["books"] = { "", "", "", "", "", "", "", "", "", "", "", "", "", "", "", "" } } }, ["param2"] = 0, ["y"] = 3, ["param1"] = 0, ["z"] = 2, ["name"] = "default:bookshelf" }, { ["x"] = 1, ["meta"] = { ["fields"] = { ["formspec"] = "size[8,7;]bgcolor[#080808BB;true]background[5,5;1,1;gui_formbg.png;true]listcolors[#00000069;#5A5A5A;#141318;#30434C;#FFF]list[context;books;0,0.3;8,2;]list[current_player;main;0,2.85;8,1;]list[current_player;main;0,4.08;8,3;8]image[0,2.85;1,1;gui_hb_bg.png]image[1,2.85;1,1;gui_hb_bg.png]image[2,2.85;1,1;gui_hb_bg.png]image[3,2.85;1,1;gui_hb_bg.png]image[4,2.85;1,1;gui_hb_bg.png]image[5,2.85;1,1;gui_hb_bg.png]image[6,2.85;1,1;gui_hb_bg.png]image[7,2.85;1,1;gui_hb_bg.png]" }, ["inventory"] = { ["books"] = { "", "", "", "", "", "", "", "", "", "", "", "", "", "", "", "" } } }, ["param2"] = 0, ["y"] = 3, ["param1"] = 0, ["z"] = 3, ["name"] = "default:bookshelf" }, { ["x"] = 1, ["meta"] = { ["fields"] = { ["formspec"] = "size[8,7;]bgcolor[#080808BB;true]background[5,5;1,1;gui_formbg.png;true]listcolors[#00000069;#5A5A5A;#141318;#30434C;#FFF]list[context;books;0,0.3;8,2;]list[current_player;main;0,2.85;8,1;]list[current_player;main;0,4.08;8,3;8]image[0,2.85;1,1;gui_hb_bg.png]image[1,2.85;1,1;gui_hb_bg.png]image[2,2.85;1,1;gui_hb_bg.png]image[3,2.85;1,1;gui_hb_bg.png]image[4,2.85;1,1;gui_hb_bg.png]image[5,2.85;1,1;gui_hb_bg.png]image[6,2.85;1,1;gui_hb_bg.png]image[7,2.85;1,1;gui_hb_bg.png]" }, ["inventory"] = { ["books"] = { "", "", "", "", "", "", "", "", "", "", "", "", "", "", "", "" } } }, ["param2"] = 0, ["y"] = 3, ["param1"] = 0, ["z"] = 4, ["name"] = "default:bookshelf" }, { ["x"] = 1, ["meta"] = { ["fields"] = { ["formspec"] = "size[8,7;]bgcolor[#080808BB;true]background[5,5;1,1;gui_formbg.png;true]listcolors[#00000069;#5A5A5A;#141318;#30434C;#FFF]list[context;books;0,0.3;8,2;]list[current_player;main;0,2.85;8,1;]list[current_player;main;0,4.08;8,3;8]image[0,2.85;1,1;gui_hb_bg.png]image[1,2.85;1,1;gui_hb_bg.png]image[2,2.85;1,1;gui_hb_bg.png]image[3,2.85;1,1;gui_hb_bg.png]image[4,2.85;1,1;gui_hb_bg.png]image[5,2.85;1,1;gui_hb_bg.png]image[6,2.85;1,1;gui_hb_bg.png]image[7,2.85;1,1;gui_hb_bg.png]" }, ["inventory"] = { ["books"] = { "", "", "", "", "", "", "", "", "", "", "", "", "", "", "", "" } } }, ["param2"] = 0, ["y"] = 3, ["param1"] = 0, ["z"] = 5, ["name"] = "default:bookshelf" }, { ["x"] = 1, ["meta"] = { ["fields"] = { ["formspec"] = "size[8,7;]bgcolor[#080808BB;true]background[5,5;1,1;gui_formbg.png;true]listcolors[#00000069;#5A5A5A;#141318;#30434C;#FFF]list[context;books;0,0.3;8,2;]list[current_player;main;0,2.85;8,1;]list[current_player;main;0,4.08;8,3;8]image[0,2.85;1,1;gui_hb_bg.png]image[1,2.85;1,1;gui_hb_bg.png]image[2,2.85;1,1;gui_hb_bg.png]image[3,2.85;1,1;gui_hb_bg.png]image[4,2.85;1,1;gui_hb_bg.png]image[5,2.85;1,1;gui_hb_bg.png]image[6,2.85;1,1;gui_hb_bg.png]image[7,2.85;1,1;gui_hb_bg.png]" }, ["inventory"] = { ["books"] = { "", "", "", "", "", "", "", "", "", "", "", "", "", "", "", "" } } }, ["param2"] = 0, ["y"] = 3, ["param1"] = 0, ["z"] = 6, ["name"] = "default:bookshelf" }, { ["x"] = 1, ["meta"] = { ["fields"] = { ["formspec"] = "size[8,7;]bgcolor[#080808BB;true]background[5,5;1,1;gui_formbg.png;true]listcolors[#00000069;#5A5A5A;#141318;#30434C;#FFF]list[context;books;0,0.3;8,2;]list[current_player;main;0,2.85;8,1;]list[current_player;main;0,4.08;8,3;8]image[0,2.85;1,1;gui_hb_bg.png]image[1,2.85;1,1;gui_hb_bg.png]image[2,2.85;1,1;gui_hb_bg.png]image[3,2.85;1,1;gui_hb_bg.png]image[4,2.85;1,1;gui_hb_bg.png]image[5,2.85;1,1;gui_hb_bg.png]image[6,2.85;1,1;gui_hb_bg.png]image[7,2.85;1,1;gui_hb_bg.png]" }, ["inventory"] = { ["books"] = { "", "", "", "", "", "", "", "", "", "", "", "", "", "", "", "" } } }, ["param2"] = 0, ["y"] = 3, ["param1"] = 0, ["z"] = 7, ["name"] = "default:bookshelf" }, { ["x"] = 1, ["meta"] = { ["fields"] = { ["formspec"] = "size[8,7;]bgcolor[#080808BB;true]background[5,5;1,1;gui_formbg.png;true]listcolors[#00000069;#5A5A5A;#141318;#30434C;#FFF]list[context;books;0,0.3;8,2;]list[current_player;main;0,2.85;8,1;]list[current_player;main;0,4.08;8,3;8]image[0,2.85;1,1;gui_hb_bg.png]image[1,2.85;1,1;gui_hb_bg.png]image[2,2.85;1,1;gui_hb_bg.png]image[3,2.85;1,1;gui_hb_bg.png]image[4,2.85;1,1;gui_hb_bg.png]image[5,2.85;1,1;gui_hb_bg.png]image[6,2.85;1,1;gui_hb_bg.png]image[7,2.85;1,1;gui_hb_bg.png]" }, ["inventory"] = { ["books"] = { "", "", "", "", "", "", "", "", "", "", "", "", "", "", "", "" } } }, ["param2"] = 0, ["y"] = 3, ["param1"] = 0, ["z"] = 8, ["name"] = "default:bookshelf" }, { ["x"] = 1, ["meta"] = { ["fields"] = { ["formspec"] = "size[8,7;]bgcolor[#080808BB;true]background[5,5;1,1;gui_formbg.png;true]listcolors[#00000069;#5A5A5A;#141318;#30434C;#FFF]list[context;books;0,0.3;8,2;]list[current_player;main;0,2.85;8,1;]list[current_player;main;0,4.08;8,3;8]image[0,2.85;1,1;gui_hb_bg.png]image[1,2.85;1,1;gui_hb_bg.png]image[2,2.85;1,1;gui_hb_bg.png]image[3,2.85;1,1;gui_hb_bg.png]image[4,2.85;1,1;gui_hb_bg.png]image[5,2.85;1,1;gui_hb_bg.png]image[6,2.85;1,1;gui_hb_bg.png]image[7,2.85;1,1;gui_hb_bg.png]" }, ["inventory"] = { ["books"] = { "", "", "", "", "", "", "", "", "", "", "", "", "", "", "", "" } } }, ["param2"] = 0, ["y"] = 3, ["param1"] = 0, ["z"] = 9, ["name"] = "default:bookshelf" }, { ["x"] = 1, ["meta"] = { ["fields"] = {  }, ["inventory"] = {  } }, ["param2"] = 0, ["y"] = 3, ["param1"] = 0, ["z"] = 10, ["name"] = "default:wood" }, { ["x"] = 1, ["meta"] = { ["fields"] = {  }, ["inventory"] = {  } }, ["param2"] = 2, ["y"] = 3, ["param1"] = 61, ["z"] = 11, ["name"] = "stairs:stair_wood" }, { ["x"] = 1, ["meta"] = { ["fields"] = {  }, ["inventory"] = {  } }, ["param2"] = 0, ["y"] = 4, ["param1"] = 63, ["z"] = 0, ["name"] = "mg:ignore" }, { ["x"] = 1, ["meta"] = { ["fields"] = {  }, ["inventory"] = {  } }, ["param2"] = 0, ["y"] = 4, ["param1"] = 187, ["z"] = 1, ["name"] = "stairs:slab_wood" }, { ["x"] = 1, ["meta"] = { ["fields"] = {  }, ["inventory"] = {  } }, ["param2"] = 1, ["y"] = 4, ["param1"] = 204, ["z"] = 2, ["name"] = "stairs:stair_wood" }, { ["x"] = 1, ["meta"] = { ["fields"] = {  }, ["inventory"] = {  } }, ["param2"] = 1, ["y"] = 4, ["param1"] = 187, ["z"] = 3, ["name"] = "stairs:stair_wood" }, { ["x"] = 1, ["meta"] = { ["fields"] = {  }, ["inventory"] = {  } }, ["param2"] = 1, ["y"] = 4, ["param1"] = 171, ["z"] = 4, ["name"] = "stairs:stair_wood" }, { ["x"] = 1, ["meta"] = { ["fields"] = {  }, ["inventory"] = {  } }, ["param2"] = 1, ["y"] = 4, ["param1"] = 155, ["z"] = 5, ["name"] = "stairs:stair_wood" }, { ["x"] = 1, ["meta"] = { ["fields"] = {  }, ["inventory"] = {  } }, ["param2"] = 1, ["y"] = 4, ["param1"] = 155, ["z"] = 6, ["name"] = "stairs:stair_wood" }, { ["x"] = 1, ["meta"] = { ["fields"] = {  }, ["inventory"] = {  } }, ["param2"] = 1, ["y"] = 4, ["param1"] = 171, ["z"] = 7, ["name"] = "stairs:stair_wood" }, { ["x"] = 1, ["meta"] = { ["fields"] = {  }, ["inventory"] = {  } }, ["param2"] = 1, ["y"] = 4, ["param1"] = 187, ["z"] = 8, ["name"] = "stairs:stair_wood" }, { ["x"] = 1, ["meta"] = { ["fields"] = {  }, ["inventory"] = {  } }, ["param2"] = 1, ["y"] = 4, ["param1"] = 204, ["z"] = 9, ["name"] = "stairs:stair_wood" }, { ["x"] = 1, ["meta"] = { ["fields"] = {  }, ["inventory"] = {  } }, ["param2"] = 0, ["y"] = 4, ["param1"] = 187, ["z"] = 10, ["name"] = "stairs:slab_wood" }, { ["x"] = 1, ["meta"] = { ["fields"] = {  }, ["inventory"] = {  } }, ["param2"] = 0, ["y"] = 4, ["param1"] = 0, ["z"] = 11, ["name"] = "mg:ignore" }, { ["x"] = 1, ["meta"] = { ["fields"] = {  }, ["inventory"] = {  } }, ["param2"] = 0, ["y"] = 5, ["param1"] = 47, ["z"] = 0, ["name"] = "mg:ignore" }, { ["x"] = 1, ["meta"] = { ["fields"] = {  }, ["inventory"] = {  } }, ["param2"] = 0, ["y"] = 5, ["param1"] = 63, ["z"] = 1, ["name"] = "mg:ignore" }, { ["x"] = 1, ["meta"] = { ["fields"] = {  }, ["inventory"] = {  } }, ["param2"] = 0, ["y"] = 5, ["param1"] = 47, ["z"] = 2, ["name"] = "mg:ignore" }, { ["x"] = 1, ["meta"] = { ["fields"] = {  }, ["inventory"] = {  } }, ["param2"] = 0, ["y"] = 5, ["param1"] = 31, ["z"] = 3, ["name"] = "mg:ignore" }, { ["x"] = 1, ["meta"] = { ["fields"] = {  }, ["inventory"] = {  } }, ["param2"] = 0, ["y"] = 5, ["param1"] = 15, ["z"] = 4, ["name"] = "mg:ignore" }, { ["x"] = 1, ["meta"] = { ["fields"] = {  }, ["inventory"] = {  } }, ["param2"] = 0, ["y"] = 5, ["param1"] = 15, ["z"] = 5, ["name"] = "mg:ignore" }, { ["x"] = 1, ["meta"] = { ["fields"] = {  }, ["inventory"] = {  } }, ["param2"] = 0, ["y"] = 5, ["param1"] = 15, ["z"] = 6, ["name"] = "mg:ignore" }, { ["x"] = 1, ["meta"] = { ["fields"] = {  }, ["inventory"] = {  } }, ["param2"] = 0, ["y"] = 5, ["param1"] = 15, ["z"] = 7, ["name"] = "mg:ignore" }, { ["x"] = 1, ["meta"] = { ["fields"] = {  }, ["inventory"] = {  } }, ["param2"] = 0, ["y"] = 5, ["param1"] = 15, ["z"] = 8, ["name"] = "mg:ignore" }, { ["x"] = 1, ["meta"] = { ["fields"] = {  }, ["inventory"] = {  } }, ["param2"] = 0, ["y"] = 5, ["param1"] = 15, ["z"] = 9, ["name"] = "mg:ignore" }, { ["x"] = 1, ["meta"] = { ["fields"] = {  }, ["inventory"] = {  } }, ["param2"] = 0, ["y"] = 5, ["param1"] = 15, ["z"] = 10, ["name"] = "mg:ignore" }, { ["x"] = 1, ["meta"] = { ["fields"] = {  }, ["inventory"] = {  } }, ["param2"] = 0, ["y"] = 5, ["param1"] = 15, ["z"] = 11, ["name"] = "mg:ignore" }, { ["x"] = 2, ["meta"] = { ["fields"] = {  }, ["inventory"] = {  } }, ["param2"] = 0, ["y"] = 0, ["param1"] = 0, ["z"] = 0, ["name"] = "default:wood" }, { ["x"] = 2, ["meta"] = { ["fields"] = {  }, ["inventory"] = {  } }, ["param2"] = 0, ["y"] = 0, ["param1"] = 0, ["z"] = 1, ["name"] = "default:wood" }, { ["x"] = 2, ["meta"] = { ["fields"] = {  }, ["inventory"] = {  } }, ["param2"] = 0, ["y"] = 0, ["param1"] = 0, ["z"] = 2, ["name"] = "default:wood" }, { ["x"] = 2, ["meta"] = { ["fields"] = {  }, ["inventory"] = {  } }, ["param2"] = 0, ["y"] = 0, ["param1"] = 0, ["z"] = 3, ["name"] = "default:wood" }, { ["x"] = 2, ["meta"] = { ["fields"] = {  }, ["inventory"] = {  } }, ["param2"] = 0, ["y"] = 0, ["param1"] = 0, ["z"] = 4, ["name"] = "default:wood" }, { ["x"] = 2, ["meta"] = { ["fields"] = {  }, ["inventory"] = {  } }, ["param2"] = 0, ["y"] = 0, ["param1"] = 15, ["z"] = 5, ["name"] = "default:wood" }, { ["x"] = 2, ["meta"] = { ["fields"] = {  }, ["inventory"] = {  } }, ["param2"] = 0, ["y"] = 0, ["param1"] = 15, ["z"] = 6, ["name"] = "default:wood" }, { ["x"] = 2, ["meta"] = { ["fields"] = {  }, ["inventory"] = {  } }, ["param2"] = 0, ["y"] = 0, ["param1"] = 15, ["z"] = 7, ["name"] = "default:wood" }, { ["x"] = 2, ["meta"] = { ["fields"] = {  }, ["inventory"] = {  } }, ["param2"] = 0, ["y"] = 0, ["param1"] = 15, ["z"] = 8, ["name"] = "default:wood" }, { ["x"] = 2, ["meta"] = { ["fields"] = {  }, ["inventory"] = {  } }, ["param2"] = 0, ["y"] = 0, ["param1"] = 15, ["z"] = 9, ["name"] = "default:wood" }, { ["x"] = 2, ["meta"] = { ["fields"] = {  }, ["inventory"] = {  } }, ["param2"] = 0, ["y"] = 0, ["param1"] = 15, ["z"] = 10, ["name"] = "default:wood" }, { ["x"] = 2, ["meta"] = { ["fields"] = {  }, ["inventory"] = {  } }, ["param2"] = 0, ["y"] = 0, ["param1"] = 15, ["z"] = 11, ["name"] = "default:wood" }, { ["x"] = 2, ["meta"] = { ["fields"] = {  }, ["inventory"] = {  } }, ["param2"] = 0, ["y"] = 1, ["param1"] = 0, ["z"] = 0, ["name"] = "default:wood" }, { ["x"] = 2, ["meta"] = { ["fields"] = { ["formspec"] = "size[8,7;]bgcolor[#080808BB;true]background[5,5;1,1;gui_formbg.png;true]listcolors[#00000069;#5A5A5A;#141318;#30434C;#FFF]list[context;books;0,0.3;8,2;]list[current_player;main;0,2.85;8,1;]list[current_player;main;0,4.08;8,3;8]image[0,2.85;1,1;gui_hb_bg.png]image[1,2.85;1,1;gui_hb_bg.png]image[2,2.85;1,1;gui_hb_bg.png]image[3,2.85;1,1;gui_hb_bg.png]image[4,2.85;1,1;gui_hb_bg.png]image[5,2.85;1,1;gui_hb_bg.png]image[6,2.85;1,1;gui_hb_bg.png]image[7,2.85;1,1;gui_hb_bg.png]" }, ["inventory"] = { ["books"] = { "", "", "", "", "", "", "", "", "", "", "", "", "", "", "", "" } } }, ["param2"] = 0, ["y"] = 1, ["param1"] = 0, ["z"] = 1, ["name"] = "default:bookshelf" }, { ["x"] = 2, ["meta"] = { ["fields"] = { ["formspec"] = "size[8,7;]bgcolor[#080808BB;true]background[5,5;1,1;gui_formbg.png;true]listcolors[#00000069;#5A5A5A;#141318;#30434C;#FFF]list[context;books;0,0.3;8,2;]list[current_player;main;0,2.85;8,1;]list[current_player;main;0,4.08;8,3;8]image[0,2.85;1,1;gui_hb_bg.png]image[1,2.85;1,1;gui_hb_bg.png]image[2,2.85;1,1;gui_hb_bg.png]image[3,2.85;1,1;gui_hb_bg.png]image[4,2.85;1,1;gui_hb_bg.png]image[5,2.85;1,1;gui_hb_bg.png]image[6,2.85;1,1;gui_hb_bg.png]image[7,2.85;1,1;gui_hb_bg.png]" }, ["inventory"] = { ["books"] = { "", "", "", "", "", "", "", "", "", "", "", "", "", "", "", "" } } }, ["param2"] = 0, ["y"] = 1, ["param1"] = 0, ["z"] = 10, ["name"] = "default:bookshelf" }, { ["x"] = 2, ["meta"] = { ["fields"] = {  }, ["inventory"] = {  } }, ["param2"] = 0, ["y"] = 1, ["param1"] = 0, ["z"] = 11, ["name"] = "default:wood" }, { ["x"] = 2, ["meta"] = { ["fields"] = {  }, ["inventory"] = {  } }, ["param2"] = 0, ["y"] = 2, ["param1"] = 0, ["z"] = 0, ["name"] = "default:wood" }, { ["x"] = 2, ["meta"] = { ["fields"] = { ["formspec"] = "size[8,7;]bgcolor[#080808BB;true]background[5,5;1,1;gui_formbg.png;true]listcolors[#00000069;#5A5A5A;#141318;#30434C;#FFF]list[context;books;0,0.3;8,2;]list[current_player;main;0,2.85;8,1;]list[current_player;main;0,4.08;8,3;8]image[0,2.85;1,1;gui_hb_bg.png]image[1,2.85;1,1;gui_hb_bg.png]image[2,2.85;1,1;gui_hb_bg.png]image[3,2.85;1,1;gui_hb_bg.png]image[4,2.85;1,1;gui_hb_bg.png]image[5,2.85;1,1;gui_hb_bg.png]image[6,2.85;1,1;gui_hb_bg.png]image[7,2.85;1,1;gui_hb_bg.png]" }, ["inventory"] = { ["books"] = { "", "default:book", "", "", "", "", "", "default:book", "default:book", "", "", "", "", "", "", "" } } }, ["param2"] = 0, ["y"] = 2, ["param1"] = 0, ["z"] = 1, ["name"] = "default:bookshelf" }, { ["x"] = 2, ["meta"] = { ["fields"] = { ["formspec"] = "size[8,7;]bgcolor[#080808BB;true]background[5,5;1,1;gui_formbg.png;true]listcolors[#00000069;#5A5A5A;#141318;#30434C;#FFF]list[context;books;0,0.3;8,2;]list[current_player;main;0,2.85;8,1;]list[current_player;main;0,4.08;8,3;8]image[0,2.85;1,1;gui_hb_bg.png]image[1,2.85;1,1;gui_hb_bg.png]image[2,2.85;1,1;gui_hb_bg.png]image[3,2.85;1,1;gui_hb_bg.png]image[4,2.85;1,1;gui_hb_bg.png]image[5,2.85;1,1;gui_hb_bg.png]image[6,2.85;1,1;gui_hb_bg.png]image[7,2.85;1,1;gui_hb_bg.png]" }, ["inventory"] = { ["books"] = { "", "default:book", "", "", "default:book", "", "", "", "", "", "", "default:book", "default:book", "", "", "" } } }, ["param2"] = 0, ["y"] = 2, ["param1"] = 0, ["z"] = 10, ["name"] = "default:bookshelf" }, { ["x"] = 2, ["meta"] = { ["fields"] = {  }, ["inventory"] = {  } }, ["param2"] = 0, ["y"] = 2, ["param1"] = 0, ["z"] = 11, ["name"] = "default:wood" }, { ["x"] = 2, ["meta"] = { ["fields"] = {  }, ["inventory"] = {  } }, ["param2"] = 0, ["y"] = 3, ["param1"] = 109, ["z"] = 0, ["name"] = "stairs:stair_wood" }, { ["x"] = 2, ["meta"] = { ["fields"] = { ["formspec"] = "size[8,7;]bgcolor[#080808BB;true]background[5,5;1,1;gui_formbg.png;true]listcolors[#00000069;#5A5A5A;#141318;#30434C;#FFF]list[context;books;0,0.3;8,2;]list[current_player;main;0,2.85;8,1;]list[current_player;main;0,4.08;8,3;8]image[0,2.85;1,1;gui_hb_bg.png]image[1,2.85;1,1;gui_hb_bg.png]image[2,2.85;1,1;gui_hb_bg.png]image[3,2.85;1,1;gui_hb_bg.png]image[4,2.85;1,1;gui_hb_bg.png]image[5,2.85;1,1;gui_hb_bg.png]image[6,2.85;1,1;gui_hb_bg.png]image[7,2.85;1,1;gui_hb_bg.png]" }, ["inventory"] = { ["books"] = { "", "", "", "", "", "", "", "", "", "", "", "", "", "", "", "" } } }, ["param2"] = 0, ["y"] = 3, ["param1"] = 0, ["z"] = 1, ["name"] = "default:bookshelf" }, { ["x"] = 2, ["meta"] = { ["fields"] = { ["formspec"] = "size[8,7;]bgcolor[#080808BB;true]background[5,5;1,1;gui_formbg.png;true]listcolors[#00000069;#5A5A5A;#141318;#30434C;#FFF]list[context;books;0,0.3;8,2;]list[current_player;main;0,2.85;8,1;]list[current_player;main;0,4.08;8,3;8]image[0,2.85;1,1;gui_hb_bg.png]image[1,2.85;1,1;gui_hb_bg.png]image[2,2.85;1,1;gui_hb_bg.png]image[3,2.85;1,1;gui_hb_bg.png]image[4,2.85;1,1;gui_hb_bg.png]image[5,2.85;1,1;gui_hb_bg.png]image[6,2.85;1,1;gui_hb_bg.png]image[7,2.85;1,1;gui_hb_bg.png]" }, ["inventory"] = { ["books"] = { "", "", "", "", "", "", "", "", "", "", "", "", "", "", "", "" } } }, ["param2"] = 0, ["y"] = 3, ["param1"] = 0, ["z"] = 10, ["name"] = "default:bookshelf" }, { ["x"] = 2, ["meta"] = { ["fields"] = {  }, ["inventory"] = {  } }, ["param2"] = 2, ["y"] = 3, ["param1"] = 77, ["z"] = 11, ["name"] = "stairs:stair_wood" }, { ["x"] = 2, ["meta"] = { ["fields"] = {  }, ["inventory"] = {  } }, ["param2"] = 0, ["y"] = 4, ["param1"] = 47, ["z"] = 0, ["name"] = "mg:ignore" }, { ["x"] = 2, ["meta"] = { ["fields"] = {  }, ["inventory"] = {  } }, ["param2"] = 0, ["y"] = 4, ["param1"] = 204, ["z"] = 1, ["name"] = "stairs:stair_wood" }, { ["x"] = 2, ["meta"] = { ["fields"] = {  }, ["inventory"] = {  } }, ["param2"] = 5, ["y"] = 4, ["param1"] = 0, ["z"] = 2, ["name"] = "default:torch" }, { ["x"] = 2, ["meta"] = { ["fields"] = {  }, ["inventory"] = {  } }, ["param2"] = 4, ["y"] = 4, ["param1"] = 0, ["z"] = 9, ["name"] = "default:torch" }, { ["x"] = 2, ["meta"] = { ["fields"] = {  }, ["inventory"] = {  } }, ["param2"] = 2, ["y"] = 4, ["param1"] = 204, ["z"] = 10, ["name"] = "stairs:stair_wood" }, { ["x"] = 2, ["meta"] = { ["fields"] = {  }, ["inventory"] = {  } }, ["param2"] = 0, ["y"] = 4, ["param1"] = 0, ["z"] = 11, ["name"] = "mg:ignore" }, { ["x"] = 2, ["meta"] = { ["fields"] = {  }, ["inventory"] = {  } }, ["param2"] = 0, ["y"] = 5, ["param1"] = 31, ["z"] = 0, ["name"] = "mg:ignore" }, { ["x"] = 2, ["meta"] = { ["fields"] = {  }, ["inventory"] = {  } }, ["param2"] = 0, ["y"] = 5, ["param1"] = 47, ["z"] = 1, ["name"] = "mg:ignore" }, { ["x"] = 2, ["meta"] = { ["fields"] = {  }, ["inventory"] = {  } }, ["param2"] = 0, ["y"] = 5, ["param1"] = 205, ["z"] = 2, ["name"] = "stairs:slab_wood" }, { ["x"] = 2, ["meta"] = { ["fields"] = {  }, ["inventory"] = {  } }, ["param2"] = 0, ["y"] = 5, ["param1"] = 189, ["z"] = 3, ["name"] = "stairs:slab_wood" }, { ["x"] = 2, ["meta"] = { ["fields"] = {  }, ["inventory"] = {  } }, ["param2"] = 0, ["y"] = 5, ["param1"] = 173, ["z"] = 4, ["name"] = "stairs:slab_wood" }, { ["x"] = 2, ["meta"] = { ["fields"] = {  }, ["inventory"] = {  } }, ["param2"] = 0, ["y"] = 5, ["param1"] = 157, ["z"] = 5, ["name"] = "stairs:slab_wood" }, { ["x"] = 2, ["meta"] = { ["fields"] = {  }, ["inventory"] = {  } }, ["param2"] = 0, ["y"] = 5, ["param1"] = 157, ["z"] = 6, ["name"] = "stairs:slab_wood" }, { ["x"] = 2, ["meta"] = { ["fields"] = {  }, ["inventory"] = {  } }, ["param2"] = 0, ["y"] = 5, ["param1"] = 173, ["z"] = 7, ["name"] = "stairs:slab_wood" }, { ["x"] = 2, ["meta"] = { ["fields"] = {  }, ["inventory"] = {  } }, ["param2"] = 0, ["y"] = 5, ["param1"] = 189, ["z"] = 8, ["name"] = "stairs:slab_wood" }, { ["x"] = 2, ["meta"] = { ["fields"] = {  }, ["inventory"] = {  } }, ["param2"] = 0, ["y"] = 5, ["param1"] = 205, ["z"] = 9, ["name"] = "stairs:slab_wood" }, { ["x"] = 2, ["meta"] = { ["fields"] = {  }, ["inventory"] = {  } }, ["param2"] = 0, ["y"] = 5, ["param1"] = 15, ["z"] = 10, ["name"] = "mg:ignore" }, { ["x"] = 2, ["meta"] = { ["fields"] = {  }, ["inventory"] = {  } }, ["param2"] = 0, ["y"] = 5, ["param1"] = 15, ["z"] = 11, ["name"] = "mg:ignore" }, { ["x"] = 3, ["meta"] = { ["fields"] = {  }, ["inventory"] = {  } }, ["param2"] = 0, ["y"] = 0, ["param1"] = 0, ["z"] = 0, ["name"] = "default:wood" }, { ["x"] = 3, ["meta"] = { ["fields"] = {  }, ["inventory"] = {  } }, ["param2"] = 0, ["y"] = 0, ["param1"] = 0, ["z"] = 1, ["name"] = "default:wood" }, { ["x"] = 3, ["meta"] = { ["fields"] = {  }, ["inventory"] = {  } }, ["param2"] = 0, ["y"] = 0, ["param1"] = 0, ["z"] = 2, ["name"] = "default:wood" }, { ["x"] = 3, ["meta"] = { ["fields"] = {  }, ["inventory"] = {  } }, ["param2"] = 0, ["y"] = 0, ["param1"] = 0, ["z"] = 3, ["name"] = "default:wood" }, { ["x"] = 3, ["meta"] = { ["fields"] = {  }, ["inventory"] = {  } }, ["param2"] = 0, ["y"] = 0, ["param1"] = 0, ["z"] = 4, ["name"] = "default:wood" }, { ["x"] = 3, ["meta"] = { ["fields"] = {  }, ["inventory"] = {  } }, ["param2"] = 0, ["y"] = 0, ["param1"] = 15, ["z"] = 5, ["name"] = "default:wood" }, { ["x"] = 3, ["meta"] = { ["fields"] = {  }, ["inventory"] = {  } }, ["param2"] = 0, ["y"] = 0, ["param1"] = 15, ["z"] = 6, ["name"] = "default:wood" }, { ["x"] = 3, ["meta"] = { ["fields"] = {  }, ["inventory"] = {  } }, ["param2"] = 0, ["y"] = 0, ["param1"] = 15, ["z"] = 7, ["name"] = "default:wood" }, { ["x"] = 3, ["meta"] = { ["fields"] = {  }, ["inventory"] = {  } }, ["param2"] = 0, ["y"] = 0, ["param1"] = 15, ["z"] = 8, ["name"] = "default:wood" }, { ["x"] = 3, ["meta"] = { ["fields"] = {  }, ["inventory"] = {  } }, ["param2"] = 0, ["y"] = 0, ["param1"] = 15, ["z"] = 9, ["name"] = "default:wood" }, { ["x"] = 3, ["meta"] = { ["fields"] = {  }, ["inventory"] = {  } }, ["param2"] = 0, ["y"] = 0, ["param1"] = 15, ["z"] = 10, ["name"] = "default:wood" }, { ["x"] = 3, ["meta"] = { ["fields"] = {  }, ["inventory"] = {  } }, ["param2"] = 0, ["y"] = 0, ["param1"] = 15, ["z"] = 11, ["name"] = "default:wood" }, { ["x"] = 3, ["meta"] = { ["fields"] = {  }, ["inventory"] = {  } }, ["param2"] = 0, ["y"] = 1, ["param1"] = 0, ["z"] = 0, ["name"] = "default:wood" }, { ["x"] = 3, ["meta"] = { ["fields"] = { ["formspec"] = "size[8,7;]bgcolor[#080808BB;true]background[5,5;1,1;gui_formbg.png;true]listcolors[#00000069;#5A5A5A;#141318;#30434C;#FFF]list[context;books;0,0.3;8,2;]list[current_player;main;0,2.85;8,1;]list[current_player;main;0,4.08;8,3;8]image[0,2.85;1,1;gui_hb_bg.png]image[1,2.85;1,1;gui_hb_bg.png]image[2,2.85;1,1;gui_hb_bg.png]image[3,2.85;1,1;gui_hb_bg.png]image[4,2.85;1,1;gui_hb_bg.png]image[5,2.85;1,1;gui_hb_bg.png]image[6,2.85;1,1;gui_hb_bg.png]image[7,2.85;1,1;gui_hb_bg.png]" }, ["inventory"] = { ["books"] = { "", "", "", "", "", "", "", "", "", "", "", "", "", "", "", "" } } }, ["param2"] = 0, ["y"] = 1, ["param1"] = 0, ["z"] = 1, ["name"] = "default:bookshelf" }, { ["x"] = 3, ["meta"] = { ["fields"] = {  }, ["inventory"] = {  } }, ["param2"] = 0, ["y"] = 1, ["param1"] = 0, ["z"] = 5, ["name"] = "default:wood" }, { ["x"] = 3, ["meta"] = { ["fields"] = { ["formspec"] = "size[8,7;]bgcolor[#080808BB;true]background[5,5;1,1;gui_formbg.png;true]listcolors[#00000069;#5A5A5A;#141318;#30434C;#FFF]list[context;books;0,0.3;8,2;]list[current_player;main;0,2.85;8,1;]list[current_player;main;0,4.08;8,3;8]image[0,2.85;1,1;gui_hb_bg.png]image[1,2.85;1,1;gui_hb_bg.png]image[2,2.85;1,1;gui_hb_bg.png]image[3,2.85;1,1;gui_hb_bg.png]image[4,2.85;1,1;gui_hb_bg.png]image[5,2.85;1,1;gui_hb_bg.png]image[6,2.85;1,1;gui_hb_bg.png]image[7,2.85;1,1;gui_hb_bg.png]" }, ["inventory"] = { ["books"] = { "", "", "", "", "", "", "", "", "", "", "", "", "", "", "", "" } } }, ["param2"] = 0, ["y"] = 1, ["param1"] = 0, ["z"] = 6, ["name"] = "default:bookshelf" }, { ["x"] = 3, ["meta"] = { ["fields"] = { ["formspec"] = "size[8,7;]bgcolor[#080808BB;true]background[5,5;1,1;gui_formbg.png;true]listcolors[#00000069;#5A5A5A;#141318;#30434C;#FFF]list[context;books;0,0.3;8,2;]list[current_player;main;0,2.85;8,1;]list[current_player;main;0,4.08;8,3;8]image[0,2.85;1,1;gui_hb_bg.png]image[1,2.85;1,1;gui_hb_bg.png]image[2,2.85;1,1;gui_hb_bg.png]image[3,2.85;1,1;gui_hb_bg.png]image[4,2.85;1,1;gui_hb_bg.png]image[5,2.85;1,1;gui_hb_bg.png]image[6,2.85;1,1;gui_hb_bg.png]image[7,2.85;1,1;gui_hb_bg.png]" }, ["inventory"] = { ["books"] = { "", "", "", "", "", "", "", "", "", "", "", "default:book", "default:book", "", "", "" } } }, ["param2"] = 0, ["y"] = 1, ["param1"] = 0, ["z"] = 7, ["name"] = "default:bookshelf" }, { ["x"] = 3, ["meta"] = { ["fields"] = { ["formspec"] = "size[8,7;]bgcolor[#080808BB;true]background[5,5;1,1;gui_formbg.png;true]listcolors[#00000069;#5A5A5A;#141318;#30434C;#FFF]list[context;books;0,0.3;8,2;]list[current_player;main;0,2.85;8,1;]list[current_player;main;0,4.08;8,3;8]image[0,2.85;1,1;gui_hb_bg.png]image[1,2.85;1,1;gui_hb_bg.png]image[2,2.85;1,1;gui_hb_bg.png]image[3,2.85;1,1;gui_hb_bg.png]image[4,2.85;1,1;gui_hb_bg.png]image[5,2.85;1,1;gui_hb_bg.png]image[6,2.85;1,1;gui_hb_bg.png]image[7,2.85;1,1;gui_hb_bg.png]" }, ["inventory"] = { ["books"] = { "", "", "", "", "", "", "", "", "", "", "", "", "", "", "", "" } } }, ["param2"] = 0, ["y"] = 1, ["param1"] = 0, ["z"] = 8, ["name"] = "default:bookshelf" }, { ["x"] = 3, ["meta"] = { ["fields"] = { ["formspec"] = "size[8,7;]bgcolor[#080808BB;true]background[5,5;1,1;gui_formbg.png;true]listcolors[#00000069;#5A5A5A;#141318;#30434C;#FFF]list[context;books;0,0.3;8,2;]list[current_player;main;0,2.85;8,1;]list[current_player;main;0,4.08;8,3;8]image[0,2.85;1,1;gui_hb_bg.png]image[1,2.85;1,1;gui_hb_bg.png]image[2,2.85;1,1;gui_hb_bg.png]image[3,2.85;1,1;gui_hb_bg.png]image[4,2.85;1,1;gui_hb_bg.png]image[5,2.85;1,1;gui_hb_bg.png]image[6,2.85;1,1;gui_hb_bg.png]image[7,2.85;1,1;gui_hb_bg.png]" }, ["inventory"] = { ["books"] = { "", "", "", "", "", "", "", "", "", "", "", "", "", "", "", "" } } }, ["param2"] = 0, ["y"] = 1, ["param1"] = 0, ["z"] = 9, ["name"] = "default:bookshelf" }, { ["x"] = 3, ["meta"] = { ["fields"] = {  }, ["inventory"] = {  } }, ["param2"] = 0, ["y"] = 1, ["param1"] = 0, ["z"] = 10, ["name"] = "default:wood" }, { ["x"] = 3, ["meta"] = { ["fields"] = {  }, ["inventory"] = {  } }, ["param2"] = 0, ["y"] = 1, ["param1"] = 0, ["z"] = 11, ["name"] = "default:wood" }, { ["x"] = 3, ["meta"] = { ["fields"] = {  }, ["inventory"] = {  } }, ["param2"] = 0, ["y"] = 2, ["param1"] = 0, ["z"] = 0, ["name"] = "default:wood" }, { ["x"] = 3, ["meta"] = { ["fields"] = { ["formspec"] = "size[8,7;]bgcolor[#080808BB;true]background[5,5;1,1;gui_formbg.png;true]listcolors[#00000069;#5A5A5A;#141318;#30434C;#FFF]list[context;books;0,0.3;8,2;]list[current_player;main;0,2.85;8,1;]list[current_player;main;0,4.08;8,3;8]image[0,2.85;1,1;gui_hb_bg.png]image[1,2.85;1,1;gui_hb_bg.png]image[2,2.85;1,1;gui_hb_bg.png]image[3,2.85;1,1;gui_hb_bg.png]image[4,2.85;1,1;gui_hb_bg.png]image[5,2.85;1,1;gui_hb_bg.png]image[6,2.85;1,1;gui_hb_bg.png]image[7,2.85;1,1;gui_hb_bg.png]" }, ["inventory"] = { ["books"] = { "", "", "", "", "", "", "", "", "", "", "", "", "", "", "", "" } } }, ["param2"] = 0, ["y"] = 2, ["param1"] = 0, ["z"] = 1, ["name"] = "default:bookshelf" }, { ["x"] = 3, ["meta"] = { ["fields"] = {  }, ["inventory"] = {  } }, ["param2"] = 4, ["y"] = 2, ["param1"] = 0, ["z"] = 4, ["name"] = "default:torch" }, { ["x"] = 3, ["meta"] = { ["fields"] = {  }, ["inventory"] = {  } }, ["param2"] = 0, ["y"] = 2, ["param1"] = 0, ["z"] = 5, ["name"] = "default:wood" }, { ["x"] = 3, ["meta"] = { ["fields"] = { ["formspec"] = "size[8,7;]bgcolor[#080808BB;true]background[5,5;1,1;gui_formbg.png;true]listcolors[#00000069;#5A5A5A;#141318;#30434C;#FFF]list[context;books;0,0.3;8,2;]list[current_player;main;0,2.85;8,1;]list[current_player;main;0,4.08;8,3;8]image[0,2.85;1,1;gui_hb_bg.png]image[1,2.85;1,1;gui_hb_bg.png]image[2,2.85;1,1;gui_hb_bg.png]image[3,2.85;1,1;gui_hb_bg.png]image[4,2.85;1,1;gui_hb_bg.png]image[5,2.85;1,1;gui_hb_bg.png]image[6,2.85;1,1;gui_hb_bg.png]image[7,2.85;1,1;gui_hb_bg.png]" }, ["inventory"] = { ["books"] = { "", "", "", "", "", "", "", "", "", "", "", "", "", "", "", "" } } }, ["param2"] = 0, ["y"] = 2, ["param1"] = 0, ["z"] = 6, ["name"] = "default:bookshelf" }, { ["x"] = 3, ["meta"] = { ["fields"] = { ["formspec"] = "size[8,7;]bgcolor[#080808BB;true]background[5,5;1,1;gui_formbg.png;true]listcolors[#00000069;#5A5A5A;#141318;#30434C;#FFF]list[context;books;0,0.3;8,2;]list[current_player;main;0,2.85;8,1;]list[current_player;main;0,4.08;8,3;8]image[0,2.85;1,1;gui_hb_bg.png]image[1,2.85;1,1;gui_hb_bg.png]image[2,2.85;1,1;gui_hb_bg.png]image[3,2.85;1,1;gui_hb_bg.png]image[4,2.85;1,1;gui_hb_bg.png]image[5,2.85;1,1;gui_hb_bg.png]image[6,2.85;1,1;gui_hb_bg.png]image[7,2.85;1,1;gui_hb_bg.png]" }, ["inventory"] = { ["books"] = { "", "", "", "", "", "", "", "", "", "", "", "", "", "", "", "" } } }, ["param2"] = 0, ["y"] = 2, ["param1"] = 0, ["z"] = 7, ["name"] = "default:bookshelf" }, { ["x"] = 3, ["meta"] = { ["fields"] = { ["formspec"] = "size[8,7;]bgcolor[#080808BB;true]background[5,5;1,1;gui_formbg.png;true]listcolors[#00000069;#5A5A5A;#141318;#30434C;#FFF]list[context;books;0,0.3;8,2;]list[current_player;main;0,2.85;8,1;]list[current_player;main;0,4.08;8,3;8]image[0,2.85;1,1;gui_hb_bg.png]image[1,2.85;1,1;gui_hb_bg.png]image[2,2.85;1,1;gui_hb_bg.png]image[3,2.85;1,1;gui_hb_bg.png]image[4,2.85;1,1;gui_hb_bg.png]image[5,2.85;1,1;gui_hb_bg.png]image[6,2.85;1,1;gui_hb_bg.png]image[7,2.85;1,1;gui_hb_bg.png]" }, ["inventory"] = { ["books"] = { "", "", "", "", "", "", "", "default:book", "", "", "", "default:book", "", "", "", "" } } }, ["param2"] = 0, ["y"] = 2, ["param1"] = 0, ["z"] = 8, ["name"] = "default:bookshelf" }, { ["x"] = 3, ["meta"] = { ["fields"] = { ["formspec"] = "size[8,7;]bgcolor[#080808BB;true]background[5,5;1,1;gui_formbg.png;true]listcolors[#00000069;#5A5A5A;#141318;#30434C;#FFF]list[context;books;0,0.3;8,2;]list[current_player;main;0,2.85;8,1;]list[current_player;main;0,4.08;8,3;8]image[0,2.85;1,1;gui_hb_bg.png]image[1,2.85;1,1;gui_hb_bg.png]image[2,2.85;1,1;gui_hb_bg.png]image[3,2.85;1,1;gui_hb_bg.png]image[4,2.85;1,1;gui_hb_bg.png]image[5,2.85;1,1;gui_hb_bg.png]image[6,2.85;1,1;gui_hb_bg.png]image[7,2.85;1,1;gui_hb_bg.png]" }, ["inventory"] = { ["books"] = { "", "", "", "", "", "", "", "", "", "", "", "", "", "", "", "" } } }, ["param2"] = 0, ["y"] = 2, ["param1"] = 0, ["z"] = 9, ["name"] = "default:bookshelf" }, { ["x"] = 3, ["meta"] = { ["fields"] = {  }, ["inventory"] = {  } }, ["param2"] = 0, ["y"] = 2, ["param1"] = 0, ["z"] = 10, ["name"] = "default:wood" }, { ["x"] = 3, ["meta"] = { ["fields"] = {  }, ["inventory"] = {  } }, ["param2"] = 0, ["y"] = 2, ["param1"] = 0, ["z"] = 11, ["name"] = "default:wood" }, { ["x"] = 3, ["meta"] = { ["fields"] = {  }, ["inventory"] = {  } }, ["param2"] = 0, ["y"] = 3, ["param1"] = 125, ["z"] = 0, ["name"] = "stairs:stair_wood" }, { ["x"] = 3, ["meta"] = { ["fields"] = { ["formspec"] = "size[8,7;]bgcolor[#080808BB;true]background[5,5;1,1;gui_formbg.png;true]listcolors[#00000069;#5A5A5A;#141318;#30434C;#FFF]list[context;books;0,0.3;8,2;]list[current_player;main;0,2.85;8,1;]list[current_player;main;0,4.08;8,3;8]image[0,2.85;1,1;gui_hb_bg.png]image[1,2.85;1,1;gui_hb_bg.png]image[2,2.85;1,1;gui_hb_bg.png]image[3,2.85;1,1;gui_hb_bg.png]image[4,2.85;1,1;gui_hb_bg.png]image[5,2.85;1,1;gui_hb_bg.png]image[6,2.85;1,1;gui_hb_bg.png]image[7,2.85;1,1;gui_hb_bg.png]" }, ["inventory"] = { ["books"] = { "", "", "", "", "", "", "", "", "", "", "", "", "", "", "", "" } } }, ["param2"] = 0, ["y"] = 3, ["param1"] = 0, ["z"] = 1, ["name"] = "default:bookshelf" }, { ["x"] = 3, ["meta"] = { ["fields"] = {  }, ["inventory"] = {  } }, ["param2"] = 0, ["y"] = 3, ["param1"] = 0, ["z"] = 5, ["name"] = "default:wood" }, { ["x"] = 3, ["meta"] = { ["fields"] = { ["formspec"] = "size[8,7;]bgcolor[#080808BB;true]background[5,5;1,1;gui_formbg.png;true]listcolors[#00000069;#5A5A5A;#141318;#30434C;#FFF]list[context;books;0,0.3;8,2;]list[current_player;main;0,2.85;8,1;]list[current_player;main;0,4.08;8,3;8]image[0,2.85;1,1;gui_hb_bg.png]image[1,2.85;1,1;gui_hb_bg.png]image[2,2.85;1,1;gui_hb_bg.png]image[3,2.85;1,1;gui_hb_bg.png]image[4,2.85;1,1;gui_hb_bg.png]image[5,2.85;1,1;gui_hb_bg.png]image[6,2.85;1,1;gui_hb_bg.png]image[7,2.85;1,1;gui_hb_bg.png]" }, ["inventory"] = { ["books"] = { "", "", "", "", "", "", "", "", "", "", "", "", "", "", "", "" } } }, ["param2"] = 0, ["y"] = 3, ["param1"] = 0, ["z"] = 6, ["name"] = "default:bookshelf" }, { ["x"] = 3, ["meta"] = { ["fields"] = { ["formspec"] = "size[8,7;]bgcolor[#080808BB;true]background[5,5;1,1;gui_formbg.png;true]listcolors[#00000069;#5A5A5A;#141318;#30434C;#FFF]list[context;books;0,0.3;8,2;]list[current_player;main;0,2.85;8,1;]list[current_player;main;0,4.08;8,3;8]image[0,2.85;1,1;gui_hb_bg.png]image[1,2.85;1,1;gui_hb_bg.png]image[2,2.85;1,1;gui_hb_bg.png]image[3,2.85;1,1;gui_hb_bg.png]image[4,2.85;1,1;gui_hb_bg.png]image[5,2.85;1,1;gui_hb_bg.png]image[6,2.85;1,1;gui_hb_bg.png]image[7,2.85;1,1;gui_hb_bg.png]" }, ["inventory"] = { ["books"] = { "", "", "", "", "", "", "", "", "", "", "", "", "", "", "", "" } } }, ["param2"] = 0, ["y"] = 3, ["param1"] = 0, ["z"] = 7, ["name"] = "default:bookshelf" }, { ["x"] = 3, ["meta"] = { ["fields"] = { ["formspec"] = "size[8,7;]bgcolor[#080808BB;true]background[5,5;1,1;gui_formbg.png;true]listcolors[#00000069;#5A5A5A;#141318;#30434C;#FFF]list[context;books;0,0.3;8,2;]list[current_player;main;0,2.85;8,1;]list[current_player;main;0,4.08;8,3;8]image[0,2.85;1,1;gui_hb_bg.png]image[1,2.85;1,1;gui_hb_bg.png]image[2,2.85;1,1;gui_hb_bg.png]image[3,2.85;1,1;gui_hb_bg.png]image[4,2.85;1,1;gui_hb_bg.png]image[5,2.85;1,1;gui_hb_bg.png]image[6,2.85;1,1;gui_hb_bg.png]image[7,2.85;1,1;gui_hb_bg.png]" }, ["inventory"] = { ["books"] = { "", "", "", "", "", "", "", "", "", "", "", "", "", "", "", "" } } }, ["param2"] = 0, ["y"] = 3, ["param1"] = 0, ["z"] = 8, ["name"] = "default:bookshelf" }, { ["x"] = 3, ["meta"] = { ["fields"] = { ["formspec"] = "size[8,7;]bgcolor[#080808BB;true]background[5,5;1,1;gui_formbg.png;true]listcolors[#00000069;#5A5A5A;#141318;#30434C;#FFF]list[context;books;0,0.3;8,2;]list[current_player;main;0,2.85;8,1;]list[current_player;main;0,4.08;8,3;8]image[0,2.85;1,1;gui_hb_bg.png]image[1,2.85;1,1;gui_hb_bg.png]image[2,2.85;1,1;gui_hb_bg.png]image[3,2.85;1,1;gui_hb_bg.png]image[4,2.85;1,1;gui_hb_bg.png]image[5,2.85;1,1;gui_hb_bg.png]image[6,2.85;1,1;gui_hb_bg.png]image[7,2.85;1,1;gui_hb_bg.png]" }, ["inventory"] = { ["books"] = { "", "", "", "", "", "", "", "", "", "", "", "", "", "", "", "" } } }, ["param2"] = 0, ["y"] = 3, ["param1"] = 0, ["z"] = 9, ["name"] = "default:bookshelf" }, { ["x"] = 3, ["meta"] = { ["fields"] = {  }, ["inventory"] = {  } }, ["param2"] = 0, ["y"] = 3, ["param1"] = 0, ["z"] = 10, ["name"] = "default:wood" }, { ["x"] = 3, ["meta"] = { ["fields"] = {  }, ["inventory"] = {  } }, ["param2"] = 2, ["y"] = 3, ["param1"] = 61, ["z"] = 11, ["name"] = "stairs:stair_wood" }, { ["x"] = 3, ["meta"] = { ["fields"] = {  }, ["inventory"] = {  } }, ["param2"] = 0, ["y"] = 4, ["param1"] = 31, ["z"] = 0, ["name"] = "mg:ignore" }, { ["x"] = 3, ["meta"] = { ["fields"] = {  }, ["inventory"] = {  } }, ["param2"] = 0, ["y"] = 4, ["param1"] = 187, ["z"] = 1, ["name"] = "stairs:stair_wood" }, { ["x"] = 3, ["meta"] = { ["fields"] = {  }, ["inventory"] = {  } }, ["param2"] = 0, ["y"] = 4, ["param1"] = 0, ["z"] = 5, ["name"] = "default:wood" }, { ["x"] = 3, ["meta"] = { ["fields"] = {  }, ["inventory"] = {  } }, ["param2"] = 3, ["y"] = 4, ["param1"] = 155, ["z"] = 6, ["name"] = "stairs:stair_wood" }, { ["x"] = 3, ["meta"] = { ["fields"] = {  }, ["inventory"] = {  } }, ["param2"] = 3, ["y"] = 4, ["param1"] = 171, ["z"] = 7, ["name"] = "stairs:stair_wood" }, { ["x"] = 3, ["meta"] = { ["fields"] = {  }, ["inventory"] = {  } }, ["param2"] = 3, ["y"] = 4, ["param1"] = 187, ["z"] = 8, ["name"] = "stairs:stair_wood" }, { ["x"] = 3, ["meta"] = { ["fields"] = {  }, ["inventory"] = {  } }, ["param2"] = 3, ["y"] = 4, ["param1"] = 204, ["z"] = 9, ["name"] = "stairs:stair_wood" }, { ["x"] = 3, ["meta"] = { ["fields"] = {  }, ["inventory"] = {  } }, ["param2"] = 0, ["y"] = 4, ["param1"] = 187, ["z"] = 10, ["name"] = "stairs:slab_wood" }, { ["x"] = 3, ["meta"] = { ["fields"] = {  }, ["inventory"] = {  } }, ["param2"] = 0, ["y"] = 4, ["param1"] = 0, ["z"] = 11, ["name"] = "mg:ignore" }, { ["x"] = 3, ["meta"] = { ["fields"] = {  }, ["inventory"] = {  } }, ["param2"] = 0, ["y"] = 5, ["param1"] = 15, ["z"] = 0, ["name"] = "mg:ignore" }, { ["x"] = 3, ["meta"] = { ["fields"] = {  }, ["inventory"] = {  } }, ["param2"] = 0, ["y"] = 5, ["param1"] = 31, ["z"] = 1, ["name"] = "mg:ignore" }, { ["x"] = 3, ["meta"] = { ["fields"] = {  }, ["inventory"] = {  } }, ["param2"] = 0, ["y"] = 5, ["param1"] = 189, ["z"] = 2, ["name"] = "stairs:slab_wood" }, { ["x"] = 3, ["meta"] = { ["fields"] = {  }, ["inventory"] = {  } }, ["param2"] = 0, ["y"] = 5, ["param1"] = 173, ["z"] = 3, ["name"] = "stairs:slab_wood" }, { ["x"] = 3, ["meta"] = { ["fields"] = {  }, ["inventory"] = {  } }, ["param2"] = 0, ["y"] = 5, ["param1"] = 173, ["z"] = 4, ["name"] = "stairs:slab_wood" }, { ["x"] = 3, ["meta"] = { ["fields"] = {  }, ["inventory"] = {  } }, ["param2"] = 0, ["y"] = 5, ["param1"] = 15, ["z"] = 5, ["name"] = "mg:ignore" }, { ["x"] = 3, ["meta"] = { ["fields"] = {  }, ["inventory"] = {  } }, ["param2"] = 0, ["y"] = 5, ["param1"] = 15, ["z"] = 6, ["name"] = "mg:ignore" }, { ["x"] = 3, ["meta"] = { ["fields"] = {  }, ["inventory"] = {  } }, ["param2"] = 0, ["y"] = 5, ["param1"] = 15, ["z"] = 7, ["name"] = "mg:ignore" }, { ["x"] = 3, ["meta"] = { ["fields"] = {  }, ["inventory"] = {  } }, ["param2"] = 0, ["y"] = 5, ["param1"] = 15, ["z"] = 8, ["name"] = "mg:ignore" }, { ["x"] = 3, ["meta"] = { ["fields"] = {  }, ["inventory"] = {  } }, ["param2"] = 0, ["y"] = 5, ["param1"] = 15, ["z"] = 9, ["name"] = "mg:ignore" }, { ["x"] = 3, ["meta"] = { ["fields"] = {  }, ["inventory"] = {  } }, ["param2"] = 0, ["y"] = 5, ["param1"] = 15, ["z"] = 10, ["name"] = "mg:ignore" }, { ["x"] = 3, ["meta"] = { ["fields"] = {  }, ["inventory"] = {  } }, ["param2"] = 0, ["y"] = 5, ["param1"] = 15, ["z"] = 11, ["name"] = "mg:ignore" }, { ["x"] = 4, ["meta"] = { ["fields"] = {  }, ["inventory"] = {  } }, ["param2"] = 0, ["y"] = 0, ["param1"] = 0, ["z"] = 0, ["name"] = "default:wood" }, { ["x"] = 4, ["meta"] = { ["fields"] = {  }, ["inventory"] = {  } }, ["param2"] = 0, ["y"] = 0, ["param1"] = 0, ["z"] = 1, ["name"] = "default:wood" }, { ["x"] = 4, ["meta"] = { ["fields"] = {  }, ["inventory"] = {  } }, ["param2"] = 0, ["y"] = 0, ["param1"] = 0, ["z"] = 2, ["name"] = "default:wood" }, { ["x"] = 4, ["meta"] = { ["fields"] = {  }, ["inventory"] = {  } }, ["param2"] = 0, ["y"] = 0, ["param1"] = 0, ["z"] = 3, ["name"] = "default:wood" }, { ["x"] = 4, ["meta"] = { ["fields"] = {  }, ["inventory"] = {  } }, ["param2"] = 0, ["y"] = 0, ["param1"] = 0, ["z"] = 4, ["name"] = "default:wood" }, { ["x"] = 4, ["meta"] = { ["fields"] = {  }, ["inventory"] = {  } }, ["param2"] = 0, ["y"] = 0, ["param1"] = 15, ["z"] = 5, ["name"] = "default:wood" }, { ["x"] = 4, ["meta"] = { ["fields"] = {  }, ["inventory"] = {  } }, ["param2"] = 0, ["y"] = 0, ["param1"] = 15, ["z"] = 6, ["name"] = "default:wood" }, { ["x"] = 4, ["meta"] = { ["fields"] = {  }, ["inventory"] = {  } }, ["param2"] = 0, ["y"] = 0, ["param1"] = 15, ["z"] = 7, ["name"] = "default:wood" }, { ["x"] = 4, ["meta"] = { ["fields"] = {  }, ["inventory"] = {  } }, ["param2"] = 0, ["y"] = 0, ["param1"] = 15, ["z"] = 8, ["name"] = "default:wood" }, { ["x"] = 4, ["meta"] = { ["fields"] = {  }, ["inventory"] = {  } }, ["param2"] = 0, ["y"] = 0, ["param1"] = 15, ["z"] = 9, ["name"] = "default:wood" }, { ["x"] = 4, ["meta"] = { ["fields"] = {  }, ["inventory"] = {  } }, ["param2"] = 0, ["y"] = 0, ["param1"] = 15, ["z"] = 10, ["name"] = "default:wood" }, { ["x"] = 4, ["meta"] = { ["fields"] = {  }, ["inventory"] = {  } }, ["param2"] = 0, ["y"] = 0, ["param1"] = 15, ["z"] = 11, ["name"] = "default:wood" }, { ["x"] = 4, ["meta"] = { ["fields"] = {  }, ["inventory"] = {  } }, ["param2"] = 0, ["y"] = 1, ["param1"] = 0, ["z"] = 0, ["name"] = "default:wood" }, { ["x"] = 4, ["meta"] = { ["fields"] = { ["formspec"] = "size[8,7;]bgcolor[#080808BB;true]background[5,5;1,1;gui_formbg.png;true]listcolors[#00000069;#5A5A5A;#141318;#30434C;#FFF]list[context;books;0,0.3;8,2;]list[current_player;main;0,2.85;8,1;]list[current_player;main;0,4.08;8,3;8]image[0,2.85;1,1;gui_hb_bg.png]image[1,2.85;1,1;gui_hb_bg.png]image[2,2.85;1,1;gui_hb_bg.png]image[3,2.85;1,1;gui_hb_bg.png]image[4,2.85;1,1;gui_hb_bg.png]image[5,2.85;1,1;gui_hb_bg.png]image[6,2.85;1,1;gui_hb_bg.png]image[7,2.85;1,1;gui_hb_bg.png]" }, ["inventory"] = { ["books"] = { "", "", "", "", "", "", "", "", "", "", "", "", "", "default:book", "", "" } } }, ["param2"] = 0, ["y"] = 1, ["param1"] = 0, ["z"] = 1, ["name"] = "default:bookshelf" }, { ["x"] = 4, ["meta"] = { ["fields"] = { ["formspec"] = "size[8,7;]bgcolor[#080808BB;true]background[5,5;1,1;gui_formbg.png;true]listcolors[#00000069;#5A5A5A;#141318;#30434C;#FFF]list[context;books;0,0.3;8,2;]list[current_player;main;0,2.85;8,1;]list[current_player;main;0,4.08;8,3;8]image[0,2.85;1,1;gui_hb_bg.png]image[1,2.85;1,1;gui_hb_bg.png]image[2,2.85;1,1;gui_hb_bg.png]image[3,2.85;1,1;gui_hb_bg.png]image[4,2.85;1,1;gui_hb_bg.png]image[5,2.85;1,1;gui_hb_bg.png]image[6,2.85;1,1;gui_hb_bg.png]image[7,2.85;1,1;gui_hb_bg.png]" }, ["inventory"] = { ["books"] = { "", "", "", "", "", "", "", "", "", "", "", "", "", "", "", "" } } }, ["param2"] = 0, ["y"] = 1, ["param1"] = 0, ["z"] = 5, ["name"] = "default:bookshelf" }, { ["x"] = 4, ["meta"] = { ["fields"] = {  }, ["inventory"] = {  } }, ["param2"] = 0, ["y"] = 1, ["param1"] = 0, ["z"] = 6, ["name"] = "default:wood" }, { ["x"] = 4, ["meta"] = { ["fields"] = {  }, ["inventory"] = {  } }, ["param2"] = 0, ["y"] = 1, ["param1"] = 0, ["z"] = 7, ["name"] = "default:wood" }, { ["x"] = 4, ["meta"] = { ["fields"] = {  }, ["inventory"] = {  } }, ["param2"] = 0, ["y"] = 1, ["param1"] = 0, ["z"] = 8, ["name"] = "default:wood" }, { ["x"] = 4, ["meta"] = { ["fields"] = {  }, ["inventory"] = {  } }, ["param2"] = 0, ["y"] = 1, ["param1"] = 0, ["z"] = 9, ["name"] = "default:wood" }, { ["x"] = 4, ["meta"] = { ["fields"] = {  }, ["inventory"] = {  } }, ["param2"] = 0, ["y"] = 1, ["param1"] = 0, ["z"] = 10, ["name"] = "default:wood" }, { ["x"] = 4, ["meta"] = { ["fields"] = {  }, ["inventory"] = {  } }, ["param2"] = 0, ["y"] = 1, ["param1"] = 0, ["z"] = 11, ["name"] = "default:wood" }, { ["x"] = 4, ["meta"] = { ["fields"] = {  }, ["inventory"] = {  } }, ["param2"] = 0, ["y"] = 2, ["param1"] = 0, ["z"] = 0, ["name"] = "default:wood" }, { ["x"] = 4, ["meta"] = { ["fields"] = { ["formspec"] = "size[8,7;]bgcolor[#080808BB;true]background[5,5;1,1;gui_formbg.png;true]listcolors[#00000069;#5A5A5A;#141318;#30434C;#FFF]list[context;books;0,0.3;8,2;]list[current_player;main;0,2.85;8,1;]list[current_player;main;0,4.08;8,3;8]image[0,2.85;1,1;gui_hb_bg.png]image[1,2.85;1,1;gui_hb_bg.png]image[2,2.85;1,1;gui_hb_bg.png]image[3,2.85;1,1;gui_hb_bg.png]image[4,2.85;1,1;gui_hb_bg.png]image[5,2.85;1,1;gui_hb_bg.png]image[6,2.85;1,1;gui_hb_bg.png]image[7,2.85;1,1;gui_hb_bg.png]" }, ["inventory"] = { ["books"] = { "", "", "", "", "", "", "", "", "", "", "", "", "", "", "", "" } } }, ["param2"] = 0, ["y"] = 2, ["param1"] = 0, ["z"] = 1, ["name"] = "default:bookshelf" }, { ["x"] = 4, ["meta"] = { ["fields"] = { ["formspec"] = "size[8,7;]bgcolor[#080808BB;true]background[5,5;1,1;gui_formbg.png;true]listcolors[#00000069;#5A5A5A;#141318;#30434C;#FFF]list[context;books;0,0.3;8,2;]list[current_player;main;0,2.85;8,1;]list[current_player;main;0,4.08;8,3;8]image[0,2.85;1,1;gui_hb_bg.png]image[1,2.85;1,1;gui_hb_bg.png]image[2,2.85;1,1;gui_hb_bg.png]image[3,2.85;1,1;gui_hb_bg.png]image[4,2.85;1,1;gui_hb_bg.png]image[5,2.85;1,1;gui_hb_bg.png]image[6,2.85;1,1;gui_hb_bg.png]image[7,2.85;1,1;gui_hb_bg.png]" }, ["inventory"] = { ["books"] = { "", "", "", "", "", "", "", "", "", "", "", "", "", "", "", "" } } }, ["param2"] = 0, ["y"] = 2, ["param1"] = 0, ["z"] = 5, ["name"] = "default:bookshelf" }, { ["x"] = 4, ["meta"] = { ["fields"] = {  }, ["inventory"] = {  } }, ["param2"] = 0, ["y"] = 2, ["param1"] = 0, ["z"] = 6, ["name"] = "default:wood" }, { ["x"] = 4, ["meta"] = { ["fields"] = {  }, ["inventory"] = {  } }, ["param2"] = 0, ["y"] = 2, ["param1"] = 0, ["z"] = 7, ["name"] = "default:wood" }, { ["x"] = 4, ["meta"] = { ["fields"] = {  }, ["inventory"] = {  } }, ["param2"] = 0, ["y"] = 2, ["param1"] = 0, ["z"] = 8, ["name"] = "default:wood" }, { ["x"] = 4, ["meta"] = { ["fields"] = {  }, ["inventory"] = {  } }, ["param2"] = 0, ["y"] = 2, ["param1"] = 0, ["z"] = 9, ["name"] = "default:wood" }, { ["x"] = 4, ["meta"] = { ["fields"] = {  }, ["inventory"] = {  } }, ["param2"] = 0, ["y"] = 2, ["param1"] = 0, ["z"] = 10, ["name"] = "default:wood" }, { ["x"] = 4, ["meta"] = { ["fields"] = {  }, ["inventory"] = {  } }, ["param2"] = 0, ["y"] = 2, ["param1"] = 0, ["z"] = 11, ["name"] = "default:wood" }, { ["x"] = 4, ["meta"] = { ["fields"] = {  }, ["inventory"] = {  } }, ["param2"] = 0, ["y"] = 3, ["param1"] = 141, ["z"] = 0, ["name"] = "stairs:stair_wood" }, { ["x"] = 4, ["meta"] = { ["fields"] = { ["formspec"] = "size[8,7;]bgcolor[#080808BB;true]background[5,5;1,1;gui_formbg.png;true]listcolors[#00000069;#5A5A5A;#141318;#30434C;#FFF]list[context;books;0,0.3;8,2;]list[current_player;main;0,2.85;8,1;]list[current_player;main;0,4.08;8,3;8]image[0,2.85;1,1;gui_hb_bg.png]image[1,2.85;1,1;gui_hb_bg.png]image[2,2.85;1,1;gui_hb_bg.png]image[3,2.85;1,1;gui_hb_bg.png]image[4,2.85;1,1;gui_hb_bg.png]image[5,2.85;1,1;gui_hb_bg.png]image[6,2.85;1,1;gui_hb_bg.png]image[7,2.85;1,1;gui_hb_bg.png]" }, ["inventory"] = { ["books"] = { "", "", "", "", "", "", "", "", "", "", "", "", "", "", "", "" } } }, ["param2"] = 0, ["y"] = 3, ["param1"] = 0, ["z"] = 1, ["name"] = "default:bookshelf" }, { ["x"] = 4, ["meta"] = { ["fields"] = { ["formspec"] = "size[8,7;]bgcolor[#080808BB;true]background[5,5;1,1;gui_formbg.png;true]listcolors[#00000069;#5A5A5A;#141318;#30434C;#FFF]list[context;books;0,0.3;8,2;]list[current_player;main;0,2.85;8,1;]list[current_player;main;0,4.08;8,3;8]image[0,2.85;1,1;gui_hb_bg.png]image[1,2.85;1,1;gui_hb_bg.png]image[2,2.85;1,1;gui_hb_bg.png]image[3,2.85;1,1;gui_hb_bg.png]image[4,2.85;1,1;gui_hb_bg.png]image[5,2.85;1,1;gui_hb_bg.png]image[6,2.85;1,1;gui_hb_bg.png]image[7,2.85;1,1;gui_hb_bg.png]" }, ["inventory"] = { ["books"] = { "", "", "", "", "", "", "", "", "", "", "", "default:book", "", "", "", "" } } }, ["param2"] = 0, ["y"] = 3, ["param1"] = 0, ["z"] = 5, ["name"] = "default:bookshelf" }, { ["x"] = 4, ["meta"] = { ["fields"] = {  }, ["inventory"] = {  } }, ["param2"] = 0, ["y"] = 3, ["param1"] = 0, ["z"] = 6, ["name"] = "default:wood" }, { ["x"] = 4, ["meta"] = { ["fields"] = {  }, ["inventory"] = {  } }, ["param2"] = 3, ["y"] = 3, ["param1"] = 9, ["z"] = 7, ["name"] = "stairs:stair_wood" }, { ["x"] = 4, ["meta"] = { ["fields"] = {  }, ["inventory"] = {  } }, ["param2"] = 3, ["y"] = 3, ["param1"] = 10, ["z"] = 8, ["name"] = "stairs:stair_wood" }, { ["x"] = 4, ["meta"] = { ["fields"] = {  }, ["inventory"] = {  } }, ["param2"] = 3, ["y"] = 3, ["param1"] = 11, ["z"] = 9, ["name"] = "stairs:stair_wood" }, { ["x"] = 4, ["meta"] = { ["fields"] = {  }, ["inventory"] = {  } }, ["param2"] = 3, ["y"] = 3, ["param1"] = 28, ["z"] = 10, ["name"] = "stairs:stair_wood" }, { ["x"] = 4, ["meta"] = { ["fields"] = {  }, ["inventory"] = {  } }, ["param2"] = 0, ["y"] = 3, ["param1"] = 45, ["z"] = 11, ["name"] = "stairs:slab_wood" }, { ["x"] = 4, ["meta"] = { ["fields"] = {  }, ["inventory"] = {  } }, ["param2"] = 0, ["y"] = 4, ["param1"] = 15, ["z"] = 0, ["name"] = "mg:ignore" }, { ["x"] = 4, ["meta"] = { ["fields"] = {  }, ["inventory"] = {  } }, ["param2"] = 0, ["y"] = 4, ["param1"] = 187, ["z"] = 1, ["name"] = "stairs:stair_wood" }, { ["x"] = 4, ["meta"] = { ["fields"] = {  }, ["inventory"] = {  } }, ["param2"] = 2, ["y"] = 4, ["param1"] = 155, ["z"] = 5, ["name"] = "stairs:stair_wood" }, { ["x"] = 4, ["meta"] = { ["fields"] = {  }, ["inventory"] = {  } }, ["param2"] = 0, ["y"] = 4, ["param1"] = 15, ["z"] = 6, ["name"] = "mg:ignore" }, { ["x"] = 4, ["meta"] = { ["fields"] = {  }, ["inventory"] = {  } }, ["param2"] = 0, ["y"] = 4, ["param1"] = 15, ["z"] = 7, ["name"] = "mg:ignore" }, { ["x"] = 4, ["meta"] = { ["fields"] = {  }, ["inventory"] = {  } }, ["param2"] = 0, ["y"] = 4, ["param1"] = 15, ["z"] = 8, ["name"] = "mg:ignore" }, { ["x"] = 4, ["meta"] = { ["fields"] = {  }, ["inventory"] = {  } }, ["param2"] = 0, ["y"] = 4, ["param1"] = 15, ["z"] = 9, ["name"] = "mg:ignore" }, { ["x"] = 4, ["meta"] = { ["fields"] = {  }, ["inventory"] = {  } }, ["param2"] = 0, ["y"] = 4, ["param1"] = 15, ["z"] = 10, ["name"] = "mg:ignore" }, { ["x"] = 4, ["meta"] = { ["fields"] = {  }, ["inventory"] = {  } }, ["param2"] = 0, ["y"] = 4, ["param1"] = 0, ["z"] = 11, ["name"] = "mg:ignore" }, { ["x"] = 4, ["meta"] = { ["fields"] = {  }, ["inventory"] = {  } }, ["param2"] = 0, ["y"] = 5, ["param1"] = 15, ["z"] = 0, ["name"] = "mg:ignore" }, { ["x"] = 4, ["meta"] = { ["fields"] = {  }, ["inventory"] = {  } }, ["param2"] = 0, ["y"] = 5, ["param1"] = 15, ["z"] = 1, ["name"] = "mg:ignore" }, { ["x"] = 4, ["meta"] = { ["fields"] = {  }, ["inventory"] = {  } }, ["param2"] = 0, ["y"] = 5, ["param1"] = 189, ["z"] = 2, ["name"] = "stairs:slab_wood" }, { ["x"] = 4, ["meta"] = { ["fields"] = {  }, ["inventory"] = {  } }, ["param2"] = 0, ["y"] = 5, ["param1"] = 173, ["z"] = 3, ["name"] = "stairs:slab_wood" }, { ["x"] = 4, ["meta"] = { ["fields"] = {  }, ["inventory"] = {  } }, ["param2"] = 0, ["y"] = 5, ["param1"] = 157, ["z"] = 4, ["name"] = "stairs:slab_wood" }, { ["x"] = 4, ["meta"] = { ["fields"] = {  }, ["inventory"] = {  } }, ["param2"] = 0, ["y"] = 5, ["param1"] = 15, ["z"] = 5, ["name"] = "mg:ignore" }, { ["x"] = 4, ["meta"] = { ["fields"] = {  }, ["inventory"] = {  } }, ["param2"] = 0, ["y"] = 5, ["param1"] = 15, ["z"] = 6, ["name"] = "mg:ignore" }, { ["x"] = 4, ["meta"] = { ["fields"] = {  }, ["inventory"] = {  } }, ["param2"] = 0, ["y"] = 5, ["param1"] = 15, ["z"] = 7, ["name"] = "mg:ignore" }, { ["x"] = 4, ["meta"] = { ["fields"] = {  }, ["inventory"] = {  } }, ["param2"] = 0, ["y"] = 5, ["param1"] = 15, ["z"] = 8, ["name"] = "mg:ignore" }, { ["x"] = 4, ["meta"] = { ["fields"] = {  }, ["inventory"] = {  } }, ["param2"] = 0, ["y"] = 5, ["param1"] = 15, ["z"] = 9, ["name"] = "mg:ignore" }, { ["x"] = 4, ["meta"] = { ["fields"] = {  }, ["inventory"] = {  } }, ["param2"] = 0, ["y"] = 5, ["param1"] = 15, ["z"] = 10, ["name"] = "mg:ignore" }, { ["x"] = 4, ["meta"] = { ["fields"] = {  }, ["inventory"] = {  } }, ["param2"] = 0, ["y"] = 5, ["param1"] = 0, ["z"] = 11, ["name"] = "mg:ignore" }, { ["x"] = 5, ["meta"] = { ["fields"] = {  }, ["inventory"] = {  } }, ["param2"] = 0, ["y"] = 0, ["param1"] = 0, ["z"] = 0, ["name"] = "default:wood" }, { ["x"] = 5, ["meta"] = { ["fields"] = {  }, ["inventory"] = {  } }, ["param2"] = 0, ["y"] = 0, ["param1"] = 0, ["z"] = 1, ["name"] = "default:wood" }, { ["x"] = 5, ["meta"] = { ["fields"] = {  }, ["inventory"] = {  } }, ["param2"] = 0, ["y"] = 0, ["param1"] = 0, ["z"] = 2, ["name"] = "default:wood" }, { ["x"] = 5, ["meta"] = { ["fields"] = {  }, ["inventory"] = {  } }, ["param2"] = 0, ["y"] = 0, ["param1"] = 0, ["z"] = 3, ["name"] = "default:wood" }, { ["x"] = 5, ["meta"] = { ["fields"] = {  }, ["inventory"] = {  } }, ["param2"] = 0, ["y"] = 0, ["param1"] = 0, ["z"] = 4, ["name"] = "default:wood" }, { ["x"] = 5, ["meta"] = { ["fields"] = {  }, ["inventory"] = {  } }, ["param2"] = 0, ["y"] = 0, ["param1"] = 15, ["z"] = 5, ["name"] = "default:wood" }, { ["x"] = 5, ["meta"] = { ["fields"] = {  }, ["inventory"] = {  } }, ["param2"] = 0, ["y"] = 0, ["param1"] = 15, ["z"] = 6, ["name"] = "default:wood" }, { ["x"] = 5, ["meta"] = { ["fields"] = {  }, ["inventory"] = {  } }, ["param2"] = 0, ["y"] = 0, ["param1"] = 0, ["z"] = 7, ["name"] = "mg:ignore" }, { ["x"] = 5, ["meta"] = { ["fields"] = {  }, ["inventory"] = {  } }, ["param2"] = 0, ["y"] = 0, ["param1"] = 15, ["z"] = 8, ["name"] = "mg:ignore" }, { ["x"] = 5, ["meta"] = { ["fields"] = {  }, ["inventory"] = {  } }, ["param2"] = 0, ["y"] = 0, ["param1"] = 15, ["z"] = 9, ["name"] = "mg:ignore" }, { ["x"] = 5, ["meta"] = { ["fields"] = {  }, ["inventory"] = {  } }, ["param2"] = 0, ["y"] = 0, ["param1"] = 15, ["z"] = 10, ["name"] = "mg:ignore" }, { ["x"] = 5, ["meta"] = { ["fields"] = {  }, ["inventory"] = {  } }, ["param2"] = 0, ["y"] = 0, ["param1"] = 0, ["z"] = 11, ["name"] = "mg:ignore" }, { ["x"] = 5, ["meta"] = { ["fields"] = {  }, ["inventory"] = {  } }, ["param2"] = 0, ["y"] = 1, ["param1"] = 141, ["z"] = 0, ["name"] = "doors:door_wood_b_1" }, { ["x"] = 5, ["meta"] = { ["fields"] = { ["formspec"] = "size[8,7;]bgcolor[#080808BB;true]background[5,5;1,1;gui_formbg.png;true]listcolors[#00000069;#5A5A5A;#141318;#30434C;#FFF]list[context;books;0,0.3;8,2;]list[current_player;main;0,2.85;8,1;]list[current_player;main;0,4.08;8,3;8]image[0,2.85;1,1;gui_hb_bg.png]image[1,2.85;1,1;gui_hb_bg.png]image[2,2.85;1,1;gui_hb_bg.png]image[3,2.85;1,1;gui_hb_bg.png]image[4,2.85;1,1;gui_hb_bg.png]image[5,2.85;1,1;gui_hb_bg.png]image[6,2.85;1,1;gui_hb_bg.png]image[7,2.85;1,1;gui_hb_bg.png]" }, ["inventory"] = { ["books"] = { "", "", "", "", "", "", "", "", "", "", "", "", "", "default:book", "", "" } } }, ["param2"] = 0, ["y"] = 1, ["param1"] = 0, ["z"] = 5, ["name"] = "default:bookshelf" }, { ["x"] = 5, ["meta"] = { ["fields"] = {  }, ["inventory"] = {  } }, ["param2"] = 0, ["y"] = 1, ["param1"] = 0, ["z"] = 6, ["name"] = "default:wood" }, { ["x"] = 5, ["meta"] = { ["fields"] = {  }, ["inventory"] = {  } }, ["param2"] = 0, ["y"] = 1, ["param1"] = 15, ["z"] = 7, ["name"] = "mg:ignore" }, { ["x"] = 5, ["meta"] = { ["fields"] = {  }, ["inventory"] = {  } }, ["param2"] = 0, ["y"] = 1, ["param1"] = 15, ["z"] = 8, ["name"] = "mg:ignore" }, { ["x"] = 5, ["meta"] = { ["fields"] = {  }, ["inventory"] = {  } }, ["param2"] = 0, ["y"] = 1, ["param1"] = 15, ["z"] = 9, ["name"] = "mg:ignore" }, { ["x"] = 5, ["meta"] = { ["fields"] = {  }, ["inventory"] = {  } }, ["param2"] = 0, ["y"] = 1, ["param1"] = 15, ["z"] = 10, ["name"] = "mg:ignore" }, { ["x"] = 5, ["meta"] = { ["fields"] = {  }, ["inventory"] = {  } }, ["param2"] = 0, ["y"] = 1, ["param1"] = 15, ["z"] = 11, ["name"] = "mg:ignore" }, { ["x"] = 5, ["meta"] = { ["fields"] = {  }, ["inventory"] = {  } }, ["param2"] = 0, ["y"] = 2, ["param1"] = 157, ["z"] = 0, ["name"] = "doors:door_wood_t_1" }, { ["x"] = 5, ["meta"] = { ["fields"] = { ["formspec"] = "size[8,7;]bgcolor[#080808BB;true]background[5,5;1,1;gui_formbg.png;true]listcolors[#00000069;#5A5A5A;#141318;#30434C;#FFF]list[context;books;0,0.3;8,2;]list[current_player;main;0,2.85;8,1;]list[current_player;main;0,4.08;8,3;8]image[0,2.85;1,1;gui_hb_bg.png]image[1,2.85;1,1;gui_hb_bg.png]image[2,2.85;1,1;gui_hb_bg.png]image[3,2.85;1,1;gui_hb_bg.png]image[4,2.85;1,1;gui_hb_bg.png]image[5,2.85;1,1;gui_hb_bg.png]image[6,2.85;1,1;gui_hb_bg.png]image[7,2.85;1,1;gui_hb_bg.png]" }, ["inventory"] = { ["books"] = { "default:book", "", "", "", "", "", "", "", "default:book", "default:book", "", "", "", "", "", "" } } }, ["param2"] = 0, ["y"] = 2, ["param1"] = 0, ["z"] = 5, ["name"] = "default:bookshelf" }, { ["x"] = 5, ["meta"] = { ["fields"] = {  }, ["inventory"] = {  } }, ["param2"] = 0, ["y"] = 2, ["param1"] = 0, ["z"] = 6, ["name"] = "default:wood" }, { ["x"] = 5, ["meta"] = { ["fields"] = {  }, ["inventory"] = {  } }, ["param2"] = 0, ["y"] = 2, ["param1"] = 15, ["z"] = 7, ["name"] = "mg:ignore" }, { ["x"] = 5, ["meta"] = { ["fields"] = {  }, ["inventory"] = {  } }, ["param2"] = 0, ["y"] = 2, ["param1"] = 15, ["z"] = 8, ["name"] = "mg:ignore" }, { ["x"] = 5, ["meta"] = { ["fields"] = {  }, ["inventory"] = {  } }, ["param2"] = 0, ["y"] = 2, ["param1"] = 15, ["z"] = 9, ["name"] = "mg:ignore" }, { ["x"] = 5, ["meta"] = { ["fields"] = {  }, ["inventory"] = {  } }, ["param2"] = 0, ["y"] = 2, ["param1"] = 15, ["z"] = 10, ["name"] = "mg:ignore" }, { ["x"] = 5, ["meta"] = { ["fields"] = {  }, ["inventory"] = {  } }, ["param2"] = 0, ["y"] = 2, ["param1"] = 15, ["z"] = 11, ["name"] = "mg:ignore" }, { ["x"] = 5, ["meta"] = { ["fields"] = {  }, ["inventory"] = {  } }, ["param2"] = 0, ["y"] = 3, ["param1"] = 157, ["z"] = 0, ["name"] = "stairs:stair_wood" }, { ["x"] = 5, ["meta"] = { ["fields"] = { ["formspec"] = "size[8,7;]bgcolor[#080808BB;true]background[5,5;1,1;gui_formbg.png;true]listcolors[#00000069;#5A5A5A;#141318;#30434C;#FFF]list[context;books;0,0.3;8,2;]list[current_player;main;0,2.85;8,1;]list[current_player;main;0,4.08;8,3;8]image[0,2.85;1,1;gui_hb_bg.png]image[1,2.85;1,1;gui_hb_bg.png]image[2,2.85;1,1;gui_hb_bg.png]image[3,2.85;1,1;gui_hb_bg.png]image[4,2.85;1,1;gui_hb_bg.png]image[5,2.85;1,1;gui_hb_bg.png]image[6,2.85;1,1;gui_hb_bg.png]image[7,2.85;1,1;gui_hb_bg.png]" }, ["inventory"] = { ["books"] = { "", "", "", "", "", "", "", "", "", "", "", "default:book", "default:book", "", "", "" } } }, ["param2"] = 0, ["y"] = 3, ["param1"] = 0, ["z"] = 1, ["name"] = "default:bookshelf" }, { ["x"] = 5, ["meta"] = { ["fields"] = { ["formspec"] = "size[8,7;]bgcolor[#080808BB;true]background[5,5;1,1;gui_formbg.png;true]listcolors[#00000069;#5A5A5A;#141318;#30434C;#FFF]list[context;books;0,0.3;8,2;]list[current_player;main;0,2.85;8,1;]list[current_player;main;0,4.08;8,3;8]image[0,2.85;1,1;gui_hb_bg.png]image[1,2.85;1,1;gui_hb_bg.png]image[2,2.85;1,1;gui_hb_bg.png]image[3,2.85;1,1;gui_hb_bg.png]image[4,2.85;1,1;gui_hb_bg.png]image[5,2.85;1,1;gui_hb_bg.png]image[6,2.85;1,1;gui_hb_bg.png]image[7,2.85;1,1;gui_hb_bg.png]" }, ["inventory"] = { ["books"] = { "", "", "", "", "", "", "", "", "", "", "", "", "", "", "", "" } } }, ["param2"] = 0, ["y"] = 3, ["param1"] = 0, ["z"] = 5, ["name"] = "default:bookshelf" }, { ["x"] = 5, ["meta"] = { ["fields"] = {  }, ["inventory"] = {  } }, ["param2"] = 2, ["y"] = 3, ["param1"] = 153, ["z"] = 6, ["name"] = "stairs:stair_wood" }, { ["x"] = 5, ["meta"] = { ["fields"] = {  }, ["inventory"] = {  } }, ["param2"] = 0, ["y"] = 3, ["param1"] = 15, ["z"] = 7, ["name"] = "mg:ignore" }, { ["x"] = 5, ["meta"] = { ["fields"] = {  }, ["inventory"] = {  } }, ["param2"] = 0, ["y"] = 3, ["param1"] = 15, ["z"] = 8, ["name"] = "mg:ignore" }, { ["x"] = 5, ["meta"] = { ["fields"] = {  }, ["inventory"] = {  } }, ["param2"] = 0, ["y"] = 3, ["param1"] = 15, ["z"] = 9, ["name"] = "mg:ignore" }, { ["x"] = 5, ["meta"] = { ["fields"] = {  }, ["inventory"] = {  } }, ["param2"] = 0, ["y"] = 3, ["param1"] = 15, ["z"] = 10, ["name"] = "mg:ignore" }, { ["x"] = 5, ["meta"] = { ["fields"] = {  }, ["inventory"] = {  } }, ["param2"] = 0, ["y"] = 3, ["param1"] = 15, ["z"] = 11, ["name"] = "mg:ignore" }, { ["x"] = 5, ["meta"] = { ["fields"] = {  }, ["inventory"] = {  } }, ["param2"] = 0, ["y"] = 4, ["param1"] = 15, ["z"] = 0, ["name"] = "mg:ignore" }, { ["x"] = 5, ["meta"] = { ["fields"] = {  }, ["inventory"] = {  } }, ["param2"] = 0, ["y"] = 4, ["param1"] = 204, ["z"] = 1, ["name"] = "stairs:stair_wood" }, { ["x"] = 5, ["meta"] = { ["fields"] = {  }, ["inventory"] = {  } }, ["param2"] = 5, ["y"] = 4, ["param1"] = 0, ["z"] = 2, ["name"] = "default:torch" }, { ["x"] = 5, ["meta"] = { ["fields"] = {  }, ["inventory"] = {  } }, ["param2"] = 2, ["y"] = 4, ["param1"] = 171, ["z"] = 5, ["name"] = "stairs:stair_wood" }, { ["x"] = 5, ["meta"] = { ["fields"] = {  }, ["inventory"] = {  } }, ["param2"] = 0, ["y"] = 4, ["param1"] = 15, ["z"] = 6, ["name"] = "mg:ignore" }, { ["x"] = 5, ["meta"] = { ["fields"] = {  }, ["inventory"] = {  } }, ["param2"] = 0, ["y"] = 4, ["param1"] = 15, ["z"] = 7, ["name"] = "mg:ignore" }, { ["x"] = 5, ["meta"] = { ["fields"] = {  }, ["inventory"] = {  } }, ["param2"] = 0, ["y"] = 4, ["param1"] = 15, ["z"] = 8, ["name"] = "mg:ignore" }, { ["x"] = 5, ["meta"] = { ["fields"] = {  }, ["inventory"] = {  } }, ["param2"] = 0, ["y"] = 4, ["param1"] = 15, ["z"] = 9, ["name"] = "mg:ignore" }, { ["x"] = 5, ["meta"] = { ["fields"] = {  }, ["inventory"] = {  } }, ["param2"] = 0, ["y"] = 4, ["param1"] = 15, ["z"] = 10, ["name"] = "mg:ignore" }, { ["x"] = 5, ["meta"] = { ["fields"] = {  }, ["inventory"] = {  } }, ["param2"] = 0, ["y"] = 4, ["param1"] = 15, ["z"] = 11, ["name"] = "mg:ignore" }, { ["x"] = 5, ["meta"] = { ["fields"] = {  }, ["inventory"] = {  } }, ["param2"] = 0, ["y"] = 5, ["param1"] = 15, ["z"] = 0, ["name"] = "mg:ignore" }, { ["x"] = 5, ["meta"] = { ["fields"] = {  }, ["inventory"] = {  } }, ["param2"] = 0, ["y"] = 5, ["param1"] = 15, ["z"] = 1, ["name"] = "mg:ignore" }, { ["x"] = 5, ["meta"] = { ["fields"] = {  }, ["inventory"] = {  } }, ["param2"] = 0, ["y"] = 5, ["param1"] = 205, ["z"] = 2, ["name"] = "stairs:slab_wood" }, { ["x"] = 5, ["meta"] = { ["fields"] = {  }, ["inventory"] = {  } }, ["param2"] = 0, ["y"] = 5, ["param1"] = 189, ["z"] = 3, ["name"] = "stairs:slab_wood" }, { ["x"] = 5, ["meta"] = { ["fields"] = {  }, ["inventory"] = {  } }, ["param2"] = 0, ["y"] = 5, ["param1"] = 173, ["z"] = 4, ["name"] = "stairs:slab_wood" }, { ["x"] = 5, ["meta"] = { ["fields"] = {  }, ["inventory"] = {  } }, ["param2"] = 0, ["y"] = 5, ["param1"] = 15, ["z"] = 5, ["name"] = "mg:ignore" }, { ["x"] = 5, ["meta"] = { ["fields"] = {  }, ["inventory"] = {  } }, ["param2"] = 0, ["y"] = 5, ["param1"] = 15, ["z"] = 6, ["name"] = "mg:ignore" }, { ["x"] = 5, ["meta"] = { ["fields"] = {  }, ["inventory"] = {  } }, ["param2"] = 0, ["y"] = 5, ["param1"] = 15, ["z"] = 7, ["name"] = "mg:ignore" }, { ["x"] = 5, ["meta"] = { ["fields"] = {  }, ["inventory"] = {  } }, ["param2"] = 0, ["y"] = 5, ["param1"] = 15, ["z"] = 8, ["name"] = "mg:ignore" }, { ["x"] = 5, ["meta"] = { ["fields"] = {  }, ["inventory"] = {  } }, ["param2"] = 0, ["y"] = 5, ["param1"] = 15, ["z"] = 9, ["name"] = "mg:ignore" }, { ["x"] = 5, ["meta"] = { ["fields"] = {  }, ["inventory"] = {  } }, ["param2"] = 0, ["y"] = 5, ["param1"] = 15, ["z"] = 10, ["name"] = "mg:ignore" }, { ["x"] = 5, ["meta"] = { ["fields"] = {  }, ["inventory"] = {  } }, ["param2"] = 0, ["y"] = 5, ["param1"] = 0, ["z"] = 11, ["name"] = "mg:ignore" }, { ["x"] = 6, ["meta"] = { ["fields"] = {  }, ["inventory"] = {  } }, ["param2"] = 0, ["y"] = 0, ["param1"] = 95, ["z"] = 0, ["name"] = "default:wood" }, { ["x"] = 6, ["meta"] = { ["fields"] = {  }, ["inventory"] = {  } }, ["param2"] = 0, ["y"] = 0, ["param1"] = 77, ["z"] = 1, ["name"] = "default:wood" }, { ["x"] = 6, ["meta"] = { ["fields"] = {  }, ["inventory"] = {  } }, ["param2"] = 0, ["y"] = 0, ["param1"] = 63, ["z"] = 2, ["name"] = "default:wood" }, { ["x"] = 6, ["meta"] = { ["fields"] = {  }, ["inventory"] = {  } }, ["param2"] = 0, ["y"] = 0, ["param1"] = 45, ["z"] = 3, ["name"] = "default:wood" }, { ["x"] = 6, ["meta"] = { ["fields"] = {  }, ["inventory"] = {  } }, ["param2"] = 0, ["y"] = 0, ["param1"] = 31, ["z"] = 4, ["name"] = "default:wood" }, { ["x"] = 6, ["meta"] = { ["fields"] = {  }, ["inventory"] = {  } }, ["param2"] = 0, ["y"] = 0, ["param1"] = 15, ["z"] = 5, ["name"] = "default:wood" }, { ["x"] = 6, ["meta"] = { ["fields"] = {  }, ["inventory"] = {  } }, ["param2"] = 0, ["y"] = 0, ["param1"] = 15, ["z"] = 6, ["name"] = "default:wood" }, { ["x"] = 6, ["meta"] = { ["fields"] = {  }, ["inventory"] = {  } }, ["param2"] = 0, ["y"] = 0, ["param1"] = 15, ["z"] = 7, ["name"] = "mg:ignore" }, { ["x"] = 6, ["meta"] = { ["fields"] = {  }, ["inventory"] = {  } }, ["param2"] = 0, ["y"] = 0, ["param1"] = 15, ["z"] = 8, ["name"] = "mg:ignore" }, { ["x"] = 6, ["meta"] = { ["fields"] = {  }, ["inventory"] = {  } }, ["param2"] = 0, ["y"] = 0, ["param1"] = 15, ["z"] = 9, ["name"] = "mg:ignore" }, { ["x"] = 6, ["meta"] = { ["fields"] = {  }, ["inventory"] = {  } }, ["param2"] = 0, ["y"] = 0, ["param1"] = 15, ["z"] = 10, ["name"] = "mg:ignore" }, { ["x"] = 6, ["meta"] = { ["fields"] = {  }, ["inventory"] = {  } }, ["param2"] = 0, ["y"] = 0, ["param1"] = 15, ["z"] = 11, ["name"] = "mg:ignore" }, { ["x"] = 6, ["meta"] = { ["fields"] = {  }, ["inventory"] = {  } }, ["param2"] = 0, ["y"] = 1, ["param1"] = 0, ["z"] = 0, ["name"] = "default:wood" }, { ["x"] = 6, ["meta"] = { ["fields"] = { ["formspec"] = "size[8,7;]bgcolor[#080808BB;true]background[5,5;1,1;gui_formbg.png;true]listcolors[#00000069;#5A5A5A;#141318;#30434C;#FFF]list[context;books;0,0.3;8,2;]list[current_player;main;0,2.85;8,1;]list[current_player;main;0,4.08;8,3;8]image[0,2.85;1,1;gui_hb_bg.png]image[1,2.85;1,1;gui_hb_bg.png]image[2,2.85;1,1;gui_hb_bg.png]image[3,2.85;1,1;gui_hb_bg.png]image[4,2.85;1,1;gui_hb_bg.png]image[5,2.85;1,1;gui_hb_bg.png]image[6,2.85;1,1;gui_hb_bg.png]image[7,2.85;1,1;gui_hb_bg.png]" }, ["inventory"] = { ["books"] = { "", "", "default:book", "", "", "", "", "", "default:book", "", "", "", "", "", "", "default:book" } } }, ["param2"] = 0, ["y"] = 1, ["param1"] = 0, ["z"] = 1, ["name"] = "default:bookshelf" }, { ["x"] = 6, ["meta"] = { ["fields"] = { ["formspec"] = "size[8,7;]bgcolor[#080808BB;true]background[5,5;1,1;gui_formbg.png;true]listcolors[#00000069;#5A5A5A;#141318;#30434C;#FFF]list[context;books;0,0.3;8,2;]list[current_player;main;0,2.85;8,1;]list[current_player;main;0,4.08;8,3;8]image[0,2.85;1,1;gui_hb_bg.png]image[1,2.85;1,1;gui_hb_bg.png]image[2,2.85;1,1;gui_hb_bg.png]image[3,2.85;1,1;gui_hb_bg.png]image[4,2.85;1,1;gui_hb_bg.png]image[5,2.85;1,1;gui_hb_bg.png]image[6,2.85;1,1;gui_hb_bg.png]image[7,2.85;1,1;gui_hb_bg.png]" }, ["inventory"] = { ["books"] = { "", "", "", "", "", "", "", "", "", "", "", "", "", "", "", "" } } }, ["param2"] = 0, ["y"] = 1, ["param1"] = 0, ["z"] = 5, ["name"] = "default:bookshelf" }, { ["x"] = 6, ["meta"] = { ["fields"] = {  }, ["inventory"] = {  } }, ["param2"] = 0, ["y"] = 1, ["param1"] = 0, ["z"] = 6, ["name"] = "default:wood" }, { ["x"] = 6, ["meta"] = { ["fields"] = {  }, ["inventory"] = {  } }, ["param2"] = 0, ["y"] = 1, ["param1"] = 15, ["z"] = 7, ["name"] = "mg:ignore" }, { ["x"] = 6, ["meta"] = { ["fields"] = {  }, ["inventory"] = {  } }, ["param2"] = 0, ["y"] = 1, ["param1"] = 15, ["z"] = 8, ["name"] = "mg:ignore" }, { ["x"] = 6, ["meta"] = { ["fields"] = {  }, ["inventory"] = {  } }, ["param2"] = 0, ["y"] = 1, ["param1"] = 15, ["z"] = 9, ["name"] = "mg:ignore" }, { ["x"] = 6, ["meta"] = { ["fields"] = {  }, ["inventory"] = {  } }, ["param2"] = 0, ["y"] = 1, ["param1"] = 15, ["z"] = 10, ["name"] = "mg:ignore" }, { ["x"] = 6, ["meta"] = { ["fields"] = {  }, ["inventory"] = {  } }, ["param2"] = 0, ["y"] = 1, ["param1"] = 15, ["z"] = 11, ["name"] = "mg:ignore" }, { ["x"] = 6, ["meta"] = { ["fields"] = {  }, ["inventory"] = {  } }, ["param2"] = 0, ["y"] = 2, ["param1"] = 0, ["z"] = 0, ["name"] = "default:wood" }, { ["x"] = 6, ["meta"] = { ["fields"] = { ["formspec"] = "size[8,7;]bgcolor[#080808BB;true]background[5,5;1,1;gui_formbg.png;true]listcolors[#00000069;#5A5A5A;#141318;#30434C;#FFF]list[context;books;0,0.3;8,2;]list[current_player;main;0,2.85;8,1;]list[current_player;main;0,4.08;8,3;8]image[0,2.85;1,1;gui_hb_bg.png]image[1,2.85;1,1;gui_hb_bg.png]image[2,2.85;1,1;gui_hb_bg.png]image[3,2.85;1,1;gui_hb_bg.png]image[4,2.85;1,1;gui_hb_bg.png]image[5,2.85;1,1;gui_hb_bg.png]image[6,2.85;1,1;gui_hb_bg.png]image[7,2.85;1,1;gui_hb_bg.png]" }, ["inventory"] = { ["books"] = { "", "", "", "", "", "", "", "", "", "", "", "", "", "", "", "" } } }, ["param2"] = 0, ["y"] = 2, ["param1"] = 0, ["z"] = 1, ["name"] = "default:bookshelf" }, { ["x"] = 6, ["meta"] = { ["fields"] = { ["formspec"] = "size[8,7;]bgcolor[#080808BB;true]background[5,5;1,1;gui_formbg.png;true]listcolors[#00000069;#5A5A5A;#141318;#30434C;#FFF]list[context;books;0,0.3;8,2;]list[current_player;main;0,2.85;8,1;]list[current_player;main;0,4.08;8,3;8]image[0,2.85;1,1;gui_hb_bg.png]image[1,2.85;1,1;gui_hb_bg.png]image[2,2.85;1,1;gui_hb_bg.png]image[3,2.85;1,1;gui_hb_bg.png]image[4,2.85;1,1;gui_hb_bg.png]image[5,2.85;1,1;gui_hb_bg.png]image[6,2.85;1,1;gui_hb_bg.png]image[7,2.85;1,1;gui_hb_bg.png]" }, ["inventory"] = { ["books"] = { "", "", "", "", "", "", "", "", "", "", "", "", "", "", "", "" } } }, ["param2"] = 0, ["y"] = 2, ["param1"] = 0, ["z"] = 5, ["name"] = "default:bookshelf" }, { ["x"] = 6, ["meta"] = { ["fields"] = {  }, ["inventory"] = {  } }, ["param2"] = 0, ["y"] = 2, ["param1"] = 0, ["z"] = 6, ["name"] = "default:wood" }, { ["x"] = 6, ["meta"] = { ["fields"] = {  }, ["inventory"] = {  } }, ["param2"] = 0, ["y"] = 2, ["param1"] = 15, ["z"] = 7, ["name"] = "mg:ignore" }, { ["x"] = 6, ["meta"] = { ["fields"] = {  }, ["inventory"] = {  } }, ["param2"] = 0, ["y"] = 2, ["param1"] = 15, ["z"] = 8, ["name"] = "mg:ignore" }, { ["x"] = 6, ["meta"] = { ["fields"] = {  }, ["inventory"] = {  } }, ["param2"] = 0, ["y"] = 2, ["param1"] = 15, ["z"] = 9, ["name"] = "mg:ignore" }, { ["x"] = 6, ["meta"] = { ["fields"] = {  }, ["inventory"] = {  } }, ["param2"] = 0, ["y"] = 2, ["param1"] = 15, ["z"] = 10, ["name"] = "mg:ignore" }, { ["x"] = 6, ["meta"] = { ["fields"] = {  }, ["inventory"] = {  } }, ["param2"] = 0, ["y"] = 2, ["param1"] = 15, ["z"] = 11, ["name"] = "mg:ignore" }, { ["x"] = 6, ["meta"] = { ["fields"] = {  }, ["inventory"] = {  } }, ["param2"] = 0, ["y"] = 3, ["param1"] = 173, ["z"] = 0, ["name"] = "stairs:stair_wood" }, { ["x"] = 6, ["meta"] = { ["fields"] = { ["formspec"] = "size[8,7;]bgcolor[#080808BB;true]background[5,5;1,1;gui_formbg.png;true]listcolors[#00000069;#5A5A5A;#141318;#30434C;#FFF]list[context;books;0,0.3;8,2;]list[current_player;main;0,2.85;8,1;]list[current_player;main;0,4.08;8,3;8]image[0,2.85;1,1;gui_hb_bg.png]image[1,2.85;1,1;gui_hb_bg.png]image[2,2.85;1,1;gui_hb_bg.png]image[3,2.85;1,1;gui_hb_bg.png]image[4,2.85;1,1;gui_hb_bg.png]image[5,2.85;1,1;gui_hb_bg.png]image[6,2.85;1,1;gui_hb_bg.png]image[7,2.85;1,1;gui_hb_bg.png]" }, ["inventory"] = { ["books"] = { "", "", "", "", "", "", "", "", "", "", "", "default:book", "", "", "", "" } } }, ["param2"] = 0, ["y"] = 3, ["param1"] = 0, ["z"] = 1, ["name"] = "default:bookshelf" }, { ["x"] = 6, ["meta"] = { ["fields"] = { ["formspec"] = "size[8,7;]bgcolor[#080808BB;true]background[5,5;1,1;gui_formbg.png;true]listcolors[#00000069;#5A5A5A;#141318;#30434C;#FFF]list[context;books;0,0.3;8,2;]list[current_player;main;0,2.85;8,1;]list[current_player;main;0,4.08;8,3;8]image[0,2.85;1,1;gui_hb_bg.png]image[1,2.85;1,1;gui_hb_bg.png]image[2,2.85;1,1;gui_hb_bg.png]image[3,2.85;1,1;gui_hb_bg.png]image[4,2.85;1,1;gui_hb_bg.png]image[5,2.85;1,1;gui_hb_bg.png]image[6,2.85;1,1;gui_hb_bg.png]image[7,2.85;1,1;gui_hb_bg.png]" }, ["inventory"] = { ["books"] = { "", "", "", "", "", "", "", "", "", "", "", "", "", "", "", "" } } }, ["param2"] = 0, ["y"] = 3, ["param1"] = 0, ["z"] = 5, ["name"] = "default:bookshelf" }, { ["x"] = 6, ["meta"] = { ["fields"] = {  }, ["inventory"] = {  } }, ["param2"] = 2, ["y"] = 3, ["param1"] = 170, ["z"] = 6, ["name"] = "stairs:stair_wood" }, { ["x"] = 6, ["meta"] = { ["fields"] = {  }, ["inventory"] = {  } }, ["param2"] = 0, ["y"] = 3, ["param1"] = 15, ["z"] = 7, ["name"] = "mg:ignore" }, { ["x"] = 6, ["meta"] = { ["fields"] = {  }, ["inventory"] = {  } }, ["param2"] = 0, ["y"] = 3, ["param1"] = 15, ["z"] = 8, ["name"] = "mg:ignore" }, { ["x"] = 6, ["meta"] = { ["fields"] = {  }, ["inventory"] = {  } }, ["param2"] = 0, ["y"] = 3, ["param1"] = 15, ["z"] = 9, ["name"] = "mg:ignore" }, { ["x"] = 6, ["meta"] = { ["fields"] = {  }, ["inventory"] = {  } }, ["param2"] = 0, ["y"] = 3, ["param1"] = 15, ["z"] = 10, ["name"] = "mg:ignore" }, { ["x"] = 6, ["meta"] = { ["fields"] = {  }, ["inventory"] = {  } }, ["param2"] = 0, ["y"] = 3, ["param1"] = 15, ["z"] = 11, ["name"] = "mg:ignore" }, { ["x"] = 6, ["meta"] = { ["fields"] = {  }, ["inventory"] = {  } }, ["param2"] = 0, ["y"] = 4, ["param1"] = 15, ["z"] = 0, ["name"] = "mg:ignore" }, { ["x"] = 6, ["meta"] = { ["fields"] = {  }, ["inventory"] = {  } }, ["param2"] = 0, ["y"] = 4, ["param1"] = 187, ["z"] = 1, ["name"] = "stairs:slab_wood" }, { ["x"] = 6, ["meta"] = { ["fields"] = {  }, ["inventory"] = {  } }, ["param2"] = 3, ["y"] = 4, ["param1"] = 204, ["z"] = 2, ["name"] = "stairs:stair_wood" }, { ["x"] = 6, ["meta"] = { ["fields"] = {  }, ["inventory"] = {  } }, ["param2"] = 3, ["y"] = 4, ["param1"] = 187, ["z"] = 3, ["name"] = "stairs:stair_wood" }, { ["x"] = 6, ["meta"] = { ["fields"] = {  }, ["inventory"] = {  } }, ["param2"] = 3, ["y"] = 4, ["param1"] = 171, ["z"] = 4, ["name"] = "stairs:stair_wood" }, { ["x"] = 6, ["meta"] = { ["fields"] = {  }, ["inventory"] = {  } }, ["param2"] = 0, ["y"] = 4, ["param1"] = 170, ["z"] = 5, ["name"] = "stairs:slab_wood" }, { ["x"] = 6, ["meta"] = { ["fields"] = {  }, ["inventory"] = {  } }, ["param2"] = 0, ["y"] = 4, ["param1"] = 15, ["z"] = 6, ["name"] = "mg:ignore" }, { ["x"] = 6, ["meta"] = { ["fields"] = {  }, ["inventory"] = {  } }, ["param2"] = 0, ["y"] = 4, ["param1"] = 15, ["z"] = 7, ["name"] = "mg:ignore" }, { ["x"] = 6, ["meta"] = { ["fields"] = {  }, ["inventory"] = {  } }, ["param2"] = 0, ["y"] = 4, ["param1"] = 15, ["z"] = 8, ["name"] = "mg:ignore" }, { ["x"] = 6, ["meta"] = { ["fields"] = {  }, ["inventory"] = {  } }, ["param2"] = 0, ["y"] = 4, ["param1"] = 15, ["z"] = 9, ["name"] = "mg:ignore" }, { ["x"] = 6, ["meta"] = { ["fields"] = {  }, ["inventory"] = {  } }, ["param2"] = 0, ["y"] = 4, ["param1"] = 15, ["z"] = 10, ["name"] = "mg:ignore" }, { ["x"] = 6, ["meta"] = { ["fields"] = {  }, ["inventory"] = {  } }, ["param2"] = 0, ["y"] = 4, ["param1"] = 15, ["z"] = 11, ["name"] = "mg:ignore" }, { ["x"] = 6, ["meta"] = { ["fields"] = {  }, ["inventory"] = {  } }, ["param2"] = 0, ["y"] = 5, ["param1"] = 15, ["z"] = 0, ["name"] = "mg:ignore" }, { ["x"] = 6, ["meta"] = { ["fields"] = {  }, ["inventory"] = {  } }, ["param2"] = 0, ["y"] = 5, ["param1"] = 15, ["z"] = 1, ["name"] = "mg:ignore" }, { ["x"] = 6, ["meta"] = { ["fields"] = {  }, ["inventory"] = {  } }, ["param2"] = 0, ["y"] = 5, ["param1"] = 15, ["z"] = 2, ["name"] = "mg:ignore" }, { ["x"] = 6, ["meta"] = { ["fields"] = {  }, ["inventory"] = {  } }, ["param2"] = 0, ["y"] = 5, ["param1"] = 15, ["z"] = 3, ["name"] = "mg:ignore" }, { ["x"] = 6, ["meta"] = { ["fields"] = {  }, ["inventory"] = {  } }, ["param2"] = 0, ["y"] = 5, ["param1"] = 15, ["z"] = 4, ["name"] = "mg:ignore" }, { ["x"] = 6, ["meta"] = { ["fields"] = {  }, ["inventory"] = {  } },